14-05-2023 00:36:44,%f INFO STARTED TIME: 00:36:44 14/05/2023
14-05-2023 00:36:47,%f INFO [INSERTED] Inserted 0010 Products to Category ID 24382
14-05-2023 00:36:49,%f INFO [INSERTED] Inserted 0003 Products to Category ID 24384
14-05-2023 00:36:53,%f INFO [INSERTED] Inserted 0008 Products to Category ID 24386
14-05-2023 00:36:54,%f INFO [INSERTED] Inserted 0003 Products to Category ID 24388
14-05-2023 00:37:55,%f INFO [INSERTED] Inserted 0112 Products to Category ID 11316
14-05-2023 00:38:16,%f INFO [INSERTED] Inserted 0060 Products to Category ID 11317
14-05-2023 00:38:17,%f INFO [INSERTED] Inserted 0001 Products to Category ID 11318
14-05-2023 00:40:10,%f INFO [INSERTED] Inserted 0219 Products to Category ID 24390
14-05-2023 00:40:11,%f INFO [INSERTED] Inserted 0002 Products to Category ID 24392
14-05-2023 00:40:11,%f INFO [INSERTED] Inserted 0001 Products to Category ID 24394
14-05-2023 00:41:00,%f INFO [INSERTED] Inserted 0081 Products to Category ID 13342
14-05-2023 00:42:13,%f INFO [INSERTED] Inserted 0144 Products to Category ID 13344
14-05-2023 00:43:13,%f INFO [INSERTED] Inserted 0122 Products to Category ID 13346
14-05-2023 00:44:12,%f INFO [INSERTED] Inserted 0127 Products to Category ID 13350
14-05-2023 00:46:05,%f INFO [INSERTED] Inserted 0217 Products to Category ID 13352
14-05-2023 00:47:20,%f INFO [INSERTED] Inserted 0151 Products to Category ID 13354
14-05-2023 00:48:17,%f INFO [INSERTED] Inserted 0120 Products to Category ID 13356
14-05-2023 00:48:50,%f INFO [INSERTED] Inserted 0046 Products to Category ID 24378
14-05-2023 00:49:22,%f INFO [INSERTED] Inserted 0084 Products to Category ID 24380
14-05-2023 00:50:22,%f INFO [INSERTED] Inserted 0119 Products to Category ID 11323
14-05-2023 00:51:00,%f INFO [INSERTED] Inserted 0066 Products to Category ID 11325
14-05-2023 00:51:02,%f INFO [INSERTED] Inserted 0004 Products to Category ID 13362
14-05-2023 00:51:11,%f INFO [INSERTED] Inserted 0023 Products to Category ID 13366
14-05-2023 00:52:51,%f INFO [INSERTED] Inserted 0172 Products to Category ID 24396
14-05-2023 00:53:15,%f INFO [INSERTED] Inserted 0062 Products to Category ID 24398
14-05-2023 00:53:19,%f INFO [INSERTED] Inserted 0009 Products to Category ID 24400
14-05-2023 00:54:04,%f INFO [INSERTED] Inserted 0072 Products to Category ID 13368
14-05-2023 00:55:08,%f INFO [INSERTED] Inserted 0138 Products to Category ID 13370
14-05-2023 00:55:20,%f INFO [INSERTED] Inserted 0032 Products to Category ID 11328
14-05-2023 00:55:52,%f INFO [INSERTED] Inserted 0042 Products to Category ID 11329
14-05-2023 00:56:05,%f INFO [INSERTED] Inserted 0035 Products to Category ID 11330
14-05-2023 00:56:06,%f INFO [INSERTED] Inserted 0002 Products to Category ID 11331
14-05-2023 01:02:59,%f INFO [INSERTED] Inserted 0819 Products to Category ID 12744
14-05-2023 01:03:06,%f INFO [INSERTED] Inserted 0018 Products to Category ID 12746
14-05-2023 01:04:13,%f INFO [INSERTED] Inserted 0141 Products to Category ID 13374
14-05-2023 01:04:45,%f INFO [INSERTED] Inserted 0038 Products to Category ID 13376
14-05-2023 01:04:58,%f INFO [INSERTED] Inserted 0032 Products to Category ID 13378
14-05-2023 01:05:07,%f INFO [INSERTED] Inserted 0023 Products to Category ID 13380
14-05-2023 01:05:58,%f INFO [INSERTED] Inserted 0091 Products to Category ID 13382
14-05-2023 01:10:27,%f INFO [INSERTED] Inserted 0557 Products to Category ID 13384
14-05-2023 01:11:24,%f INFO [INSERTED] Inserted 0107 Products to Category ID 13386
14-05-2023 01:12:26,%f INFO [INSERTED] Inserted 0123 Products to Category ID 13388
14-05-2023 01:12:30,%f INFO [INSERTED] Inserted 0009 Products to Category ID 11333
14-05-2023 01:25:22,%f INFO [INSERTED] Inserted 1523 Products to Category ID 11334
14-05-2023 01:26:11,%f INFO [INSERTED] Inserted 0100 Products to Category ID 46516
14-05-2023 01:26:12,%f INFO [INSERTED] Inserted 0002 Products to Category ID 1588
14-05-2023 01:26:16,%f INFO [INSERTED] Inserted 0011 Products to Category ID 11727
14-05-2023 01:43:08,%f INFO [INSERTED] Inserted 2000 Products to Category ID 1583
14-05-2023 02:00:04,%f INFO [INSERTED] Inserted 2000 Products to Category ID 1601
14-05-2023 02:16:55,%f INFO [INSERTED] Inserted 2000 Products to Category ID 17170
14-05-2023 02:19:57,%f INFO [INSERTED] Inserted 0353 Products to Category ID 17174
14-05-2023 02:30:10,%f INFO [INSERTED] Inserted 1223 Products to Category ID 2347
14-05-2023 02:40:00,%f INFO [INSERTED] Inserted 1159 Products to Category ID 3422
14-05-2023 02:43:54,%f INFO [INSERTED] Inserted 0464 Products to Category ID 3424
14-05-2023 02:54:48,%f INFO [INSERTED] Inserted 1290 Products to Category ID 3426
14-05-2023 02:54:48,%f INFO [INSERTED] Inserted 0001 Products to Category ID 11667
14-05-2023 02:54:49,%f INFO [INSERTED] Inserted 0002 Products to Category ID 11673
14-05-2023 02:54:52,%f INFO [INSERTED] Inserted 0005 Products to Category ID 11695
14-05-2023 02:57:25,%f INFO [INSERTED] Inserted 0323 Products to Category ID 5872
14-05-2023 03:00:46,%f INFO [INSERTED] Inserted 0372 Products to Category ID 5893
14-05-2023 03:05:13,%f INFO [INSERTED] Inserted 0548 Products to Category ID 8206
14-05-2023 03:15:55,%f INFO [INSERTED] Inserted 1249 Products to Category ID 8227
14-05-2023 03:16:27,%f INFO [INSERTED] Inserted 0091 Products to Category ID 11759
14-05-2023 03:17:55,%f INFO [INSERTED] Inserted 0150 Products to Category ID 11767
14-05-2023 03:17:56,%f INFO [INSERTED] Inserted 0002 Products to Category ID 11769
14-05-2023 03:19:14,%f INFO [INSERTED] Inserted 0166 Products to Category ID 1596
14-05-2023 03:19:15,%f INFO [INSERTED] Inserted 0001 Products to Category ID 11771
14-05-2023 03:19:30,%f INFO [INSERTED] Inserted 0036 Products to Category ID 1600
14-05-2023 03:20:11,%f INFO [INSERTED] Inserted 0086 Products to Category ID 1604
14-05-2023 03:21:04,%f INFO [INSERTED] Inserted 0084 Products to Category ID 1640
14-05-2023 03:21:57,%f INFO [INSERTED] Inserted 0099 Products to Category ID 2346
14-05-2023 03:22:09,%f INFO [INSERTED] Inserted 0034 Products to Category ID 8188
14-05-2023 03:22:14,%f INFO [INSERTED] Inserted 0010 Products to Category ID 11779
14-05-2023 03:23:08,%f INFO [INSERTED] Inserted 0110 Products to Category ID 1605
14-05-2023 03:24:56,%f INFO [INSERTED] Inserted 0202 Products to Category ID 1607
14-05-2023 03:26:05,%f INFO [INSERTED] Inserted 0134 Products to Category ID 1608
14-05-2023 03:27:21,%f INFO [INSERTED] Inserted 0168 Products to Category ID 1641
14-05-2023 03:27:21,%f INFO [INSERTED] Inserted 0001 Products to Category ID 8191
14-05-2023 03:27:22,%f ERROR Traceback (most recent call last):
  File "/home/ngkhachuy/PROJECT/DEC_PJ4_TIKI.VN/get_product_API.py", line 140, in <module>
    mycol.insert_many(LIST_PRODUCT)
  File "/home/ngkhachuy/anaconda3/lib/python3.9/site-packages/pymongo/_csot.py", line 105, in csot_wrapper
    return func(self, *args, **kwargs)
  File "/home/ngkhachuy/anaconda3/lib/python3.9/site-packages/pymongo/collection.py", line 698, in insert_many
    raise TypeError("documents must be a non-empty list")
TypeError: documents must be a non-empty list

14-05-2023 03:27:22,%f ERROR ERROR AT CATEGORY: 11795
14-05-2023 03:27:22,%f ERROR ERROR AT PRODUCT: 132814596
14-05-2023 03:27:22,%f INFO STARTED TIME  : 00:36:44 14/05/2023
14-05-2023 03:27:22,%f INFO FINISHED TIME : 03:27:22 14/05/2023
14-05-2023 03:27:22,%f INFO EXECUTION TINE: 2:50:38.289267
14-05-2023 03:27:22,%f INFO NUMBER OF REQUEST HAD BEEN SENT: 20496
14-05-2023 06:32:21 INFO STARTED TIME: 06:32:21 14/05/2023
14-05-2023 06:32:21 INFO [INSERTED] Inserted 0000 Products to Category ID 11795
14-05-2023 06:32:25 INFO [INSERTED] Inserted 0009 Products to Category ID 11797
14-05-2023 06:32:46 INFO [INSERTED] Inserted 0055 Products to Category ID 11799
14-05-2023 06:35:53 INFO [INSERTED] Inserted 0388 Products to Category ID 1609
14-05-2023 06:35:59 INFO [INSERTED] Inserted 0014 Products to Category ID 1611
14-05-2023 06:38:38 INFO [INSERTED] Inserted 0304 Products to Category ID 1612
14-05-2023 06:38:47 INFO [INSERTED] Inserted 0024 Products to Category ID 1614
14-05-2023 06:41:12 INFO [INSERTED] Inserted 0271 Products to Category ID 17184
14-05-2023 06:43:25 INFO [INSERTED] Inserted 0265 Products to Category ID 8192
14-05-2023 06:48:32 INFO [INSERTED] Inserted 0607 Products to Category ID 8189
14-05-2023 06:51:31 INFO [INSERTED] Inserted 0361 Products to Category ID 8190
14-05-2023 07:08:26 INFO [INSERTED] Inserted 2000 Products to Category ID 8193
14-05-2023 07:13:42 INFO [INSERTED] Inserted 0643 Products to Category ID 8194
14-05-2023 07:16:21 INFO [INSERTED] Inserted 0301 Products to Category ID 8196
14-05-2023 07:23:31 INFO [INSERTED] Inserted 0857 Products to Category ID 8197
14-05-2023 07:31:18 INFO [INSERTED] Inserted 0911 Products to Category ID 8198
14-05-2023 07:31:26 INFO [INSERTED] Inserted 0020 Products to Category ID 8228
14-05-2023 07:31:46 INFO [INSERTED] Inserted 0050 Products to Category ID 11815
14-05-2023 07:33:35 INFO [INSERTED] Inserted 0220 Products to Category ID 11827
14-05-2023 07:34:23 INFO [INSERTED] Inserted 0072 Products to Category ID 11829
14-05-2023 07:34:44 INFO [INSERTED] Inserted 0054 Products to Category ID 17180
14-05-2023 07:39:18 INFO [INSERTED] Inserted 0539 Products to Category ID 1623
14-05-2023 07:41:25 INFO [INSERTED] Inserted 0247 Products to Category ID 7061
14-05-2023 07:43:34 INFO [INSERTED] Inserted 0264 Products to Category ID 11817
14-05-2023 07:44:29 INFO [INSERTED] Inserted 0103 Products to Category ID 11819
14-05-2023 07:47:40 INFO [INSERTED] Inserted 0382 Products to Category ID 11821
14-05-2023 07:47:47 INFO [INSERTED] Inserted 0017 Products to Category ID 11823
14-05-2023 07:49:32 INFO [INSERTED] Inserted 0200 Products to Category ID 11825
14-05-2023 07:49:49 INFO [INSERTED] Inserted 0047 Products to Category ID 17176
14-05-2023 07:50:20 INFO [INSERTED] Inserted 0041 Products to Category ID 17178
14-05-2023 07:50:23 INFO [INSERTED] Inserted 0006 Products to Category ID 17182
14-05-2023 08:02:25 INFO [INSERTED] Inserted 1434 Products to Category ID 1613
14-05-2023 08:07:27 INFO [INSERTED] Inserted 0604 Products to Category ID 1616
14-05-2023 08:15:40 INFO [INSERTED] Inserted 0985 Products to Category ID 8223
14-05-2023 08:16:40 INFO [INSERTED] Inserted 0115 Products to Category ID 11735
14-05-2023 08:16:50 INFO [INSERTED] Inserted 0028 Products to Category ID 11737
14-05-2023 08:17:49 INFO [INSERTED] Inserted 0118 Products to Category ID 11753
14-05-2023 08:19:13 INFO [INSERTED] Inserted 0138 Products to Category ID 11755
14-05-2023 08:19:23 INFO [INSERTED] Inserted 0024 Products to Category ID 10218
14-05-2023 08:19:26 INFO [INSERTED] Inserted 0007 Products to Category ID 10220
14-05-2023 08:19:38 INFO [INSERTED] Inserted 0030 Products to Category ID 10225
14-05-2023 08:20:32 INFO [INSERTED] Inserted 0096 Products to Category ID 17460
14-05-2023 08:20:53 INFO [INSERTED] Inserted 0061 Products to Category ID 11731
14-05-2023 08:22:58 INFO [INSERTED] Inserted 0244 Products to Category ID 4413
14-05-2023 08:26:33 INFO [INSERTED] Inserted 0394 Products to Category ID 8216
14-05-2023 08:31:17 INFO [INSERTED] Inserted 0578 Products to Category ID 8217
14-05-2023 08:31:28 INFO [INSERTED] Inserted 0026 Products to Category ID 11739
14-05-2023 08:34:36 INFO [INSERTED] Inserted 0379 Products to Category ID 11741
14-05-2023 08:34:41 INFO [INSERTED] Inserted 0011 Products to Category ID 11743
14-05-2023 08:34:53 INFO [INSERTED] Inserted 0031 Products to Category ID 17160
14-05-2023 08:35:57 INFO [INSERTED] Inserted 0127 Products to Category ID 11747
14-05-2023 08:40:49 INFO [INSERTED] Inserted 0575 Products to Category ID 17162
14-05-2023 08:44:42 INFO [INSERTED] Inserted 0450 Products to Category ID 8220
14-05-2023 08:44:46 INFO [INSERTED] Inserted 0008 Products to Category ID 8221
14-05-2023 08:45:49 INFO [INSERTED] Inserted 0136 Products to Category ID 3449
14-05-2023 08:48:27 INFO [INSERTED] Inserted 0294 Products to Category ID 5900
14-05-2023 08:48:31 INFO [INSERTED] Inserted 0011 Products to Category ID 11729
14-05-2023 09:05:24 INFO [INSERTED] Inserted 2000 Products to Category ID 13878
14-05-2023 09:05:33 INFO [INSERTED] Inserted 0022 Products to Category ID 1598
14-05-2023 09:06:32 INFO [INSERTED] Inserted 0119 Products to Category ID 2348
14-05-2023 09:06:37 INFO [INSERTED] Inserted 0010 Products to Category ID 11749
14-05-2023 09:06:42 INFO [INSERTED] Inserted 0010 Products to Category ID 11751
14-05-2023 09:08:42 INFO [INSERTED] Inserted 0232 Products to Category ID 8226
14-05-2023 09:08:45 INFO [INSERTED] Inserted 0008 Products to Category ID 8229
14-05-2023 09:14:42 INFO [INSERTED] Inserted 0712 Products to Category ID 8308
14-05-2023 09:19:24 INFO [INSERTED] Inserted 0535 Products to Category ID 8309
14-05-2023 09:20:51 INFO [INSERTED] Inserted 0191 Products to Category ID 10228
14-05-2023 09:26:17 INFO [INSERTED] Inserted 0637 Products to Category ID 11833
14-05-2023 09:30:18 INFO [INSERTED] Inserted 0464 Products to Category ID 11835
14-05-2023 09:30:33 INFO [INSERTED] Inserted 0043 Products to Category ID 11837
14-05-2023 09:33:18 INFO [INSERTED] Inserted 0324 Products to Category ID 1626
14-05-2023 09:36:26 INFO [INSERTED] Inserted 0371 Products to Category ID 1627
14-05-2023 09:37:40 INFO [INSERTED] Inserted 0159 Products to Category ID 1628
14-05-2023 09:38:48 INFO [INSERTED] Inserted 0139 Products to Category ID 53348
14-05-2023 09:44:23 INFO [INSERTED] Inserted 0644 Products to Category ID 17186
14-05-2023 09:44:42 INFO [INSERTED] Inserted 0051 Products to Category ID 1728
14-05-2023 09:50:37 INFO [INSERTED] Inserted 0702 Products to Category ID 1752
14-05-2023 09:51:27 INFO [INSERTED] Inserted 0081 Products to Category ID 4408
14-05-2023 09:51:33 INFO [INSERTED] Inserted 0016 Products to Category ID 8176
14-05-2023 09:56:49 INFO [INSERTED] Inserted 0646 Products to Category ID 8300
14-05-2023 10:07:43 INFO [INSERTED] Inserted 1280 Products to Category ID 1636
14-05-2023 10:13:20 INFO [INSERTED] Inserted 0655 Products to Category ID 1637
14-05-2023 10:15:24 INFO [INSERTED] Inserted 0246 Products to Category ID 11689
14-05-2023 10:19:36 INFO [INSERTED] Inserted 0515 Products to Category ID 11937
14-05-2023 10:22:03 INFO [INSERTED] Inserted 0286 Products to Category ID 11939
14-05-2023 10:25:32 INFO [INSERTED] Inserted 0414 Products to Category ID 11803
14-05-2023 10:25:35 INFO [INSERTED] Inserted 0007 Products to Category ID 11807
14-05-2023 10:25:36 INFO [INSERTED] Inserted 0002 Products to Category ID 11809
14-05-2023 10:25:37 INFO [INSERTED] Inserted 0001 Products to Category ID 11811
14-05-2023 10:30:44 INFO [INSERTED] Inserted 0593 Products to Category ID 8199
14-05-2023 10:30:53 INFO [INSERTED] Inserted 0023 Products to Category ID 8200
14-05-2023 10:40:36 INFO [INSERTED] Inserted 1126 Products to Category ID 8201
14-05-2023 10:50:04 INFO [INSERTED] Inserted 1134 Products to Category ID 8202
14-05-2023 10:50:17 INFO [INSERTED] Inserted 0005 Products to Category ID 8204
14-05-2023 11:06:52 INFO [INSERTED] Inserted 2000 Products to Category ID 8205
14-05-2023 11:23:45 INFO [INSERTED] Inserted 2000 Products to Category ID 1634
14-05-2023 11:29:47 INFO [INSERTED] Inserted 0719 Products to Category ID 5905
14-05-2023 11:35:19 INFO [INSERTED] Inserted 0632 Products to Category ID 11933
14-05-2023 11:51:24 INFO [INSERTED] Inserted 1914 Products to Category ID 11935
14-05-2023 11:56:18 INFO [INSERTED] Inserted 0577 Products to Category ID 8165
14-05-2023 11:58:23 INFO [INSERTED] Inserted 0259 Products to Category ID 11831
14-05-2023 12:02:49 ERROR Traceback (most recent call last):
  File "/home/ngkhachuy/anaconda3/lib/python3.9/site-packages/urllib3/response.py", line 761, in _update_chunk_length
    self.chunk_left = int(line, 16)
ValueError: invalid literal for int() with base 16: b''

During handling of the above exception, another exception occurred:

Traceback (most recent call last):
  File "/home/ngkhachuy/anaconda3/lib/python3.9/site-packages/urllib3/response.py", line 444, in _error_catcher
    yield
  File "/home/ngkhachuy/anaconda3/lib/python3.9/site-packages/urllib3/response.py", line 828, in read_chunked
    self._update_chunk_length()
  File "/home/ngkhachuy/anaconda3/lib/python3.9/site-packages/urllib3/response.py", line 765, in _update_chunk_length
    raise InvalidChunkLength(self, line)
urllib3.exceptions.InvalidChunkLength: InvalidChunkLength(got length b'', 0 bytes read)

During handling of the above exception, another exception occurred:

Traceback (most recent call last):
  File "/home/ngkhachuy/anaconda3/lib/python3.9/site-packages/requests/models.py", line 816, in generate
    yield from self.raw.stream(chunk_size, decode_content=True)
  File "/home/ngkhachuy/anaconda3/lib/python3.9/site-packages/urllib3/response.py", line 624, in stream
    for line in self.read_chunked(amt, decode_content=decode_content):
  File "/home/ngkhachuy/anaconda3/lib/python3.9/site-packages/urllib3/response.py", line 857, in read_chunked
    self._original_response.close()
  File "/home/ngkhachuy/anaconda3/lib/python3.9/contextlib.py", line 137, in __exit__
    self.gen.throw(typ, value, traceback)
  File "/home/ngkhachuy/anaconda3/lib/python3.9/site-packages/urllib3/response.py", line 461, in _error_catcher
    raise ProtocolError("Connection broken: %r" % e, e)
urllib3.exceptions.ProtocolError: ("Connection broken: InvalidChunkLength(got length b'', 0 bytes read)", InvalidChunkLength(got length b'', 0 bytes read))

During handling of the above exception, another exception occurred:

Traceback (most recent call last):
  File "/home/ngkhachuy/PROJECT/DEC_PJ4_TIKI.VN/get_product_API.py", line 85, in <module>
    prod_detail = COMMON.send_get_request(PRODUCT_DETAIL_API % p_id)
  File "/home/ngkhachuy/PROJECT/DEC_PJ4_TIKI.VN/COMMON.py", line 25, in send_get_request
    res_tmp = requests.get(url, headers={"user-agent":
  File "/home/ngkhachuy/anaconda3/lib/python3.9/site-packages/requests/api.py", line 73, in get
    return request("get", url, params=params, **kwargs)
  File "/home/ngkhachuy/anaconda3/lib/python3.9/site-packages/requests/api.py", line 59, in request
    return session.request(method=method, url=url, **kwargs)
  File "/home/ngkhachuy/anaconda3/lib/python3.9/site-packages/requests/sessions.py", line 587, in request
    resp = self.send(prep, **send_kwargs)
  File "/home/ngkhachuy/anaconda3/lib/python3.9/site-packages/requests/sessions.py", line 745, in send
    r.content
  File "/home/ngkhachuy/anaconda3/lib/python3.9/site-packages/requests/models.py", line 899, in content
    self._content = b"".join(self.iter_content(CONTENT_CHUNK_SIZE)) or b""
  File "/home/ngkhachuy/anaconda3/lib/python3.9/site-packages/requests/models.py", line 818, in generate
    raise ChunkedEncodingError(e)
requests.exceptions.ChunkedEncodingError: ("Connection broken: InvalidChunkLength(got length b'', 0 bytes read)", InvalidChunkLength(got length b'', 0 bytes read))

14-05-2023 12:02:49 ERROR ERROR AT CATEGORY: 11941
14-05-2023 12:02:49 ERROR ERROR AT PRODUCT: 192259873
14-05-2023 12:02:49 INFO STARTED TIME  : 06:32:21 14/05/2023
14-05-2023 12:02:49 INFO FINISHED TIME : 12:02:49 14/05/2023
14-05-2023 12:02:49 INFO EXECUTION TINE: 5:30:28.200138
14-05-2023 12:02:49 INFO NUMBER OF REQUEST HAD BEEN SENT: 39667
14-05-2023 12:27:04 INFO STARTED TIME: 12:27:04 14/05/2023
14-05-2023 12:35:29 INFO [INSERTED] Inserted 0975 Products to Category ID 11941
14-05-2023 12:39:47 INFO [INSERTED] Inserted 0555 Products to Category ID 11943
14-05-2023 12:51:26 INFO [INSERTED] Inserted 1369 Products to Category ID 2334
14-05-2023 13:06:16 INFO [INSERTED] Inserted 1760 Products to Category ID 7064
14-05-2023 13:23:10 INFO [INSERTED] Inserted 2000 Products to Category ID 8167
14-05-2023 13:24:07 ERROR Traceback (most recent call last):
  File "/home/ngkhachuy/PROJECT/DEC_PJ4_TIKI.VN/get_product_API.py", line 85, in <module>
    prod_detail = COMMON.send_get_request(PRODUCT_DETAIL_API % p_id)
  File "/home/ngkhachuy/PROJECT/DEC_PJ4_TIKI.VN/COMMON.py", line 34, in send_get_request
    return json.loads(res_tmp.decode('utf-8'))
  File "/home/ngkhachuy/anaconda3/lib/python3.9/json/__init__.py", line 346, in loads
    return _default_decoder.decode(s)
  File "/home/ngkhachuy/anaconda3/lib/python3.9/json/decoder.py", line 337, in decode
    obj, end = self.raw_decode(s, idx=_w(s, 0).end())
  File "/home/ngkhachuy/anaconda3/lib/python3.9/json/decoder.py", line 355, in raw_decode
    raise JSONDecodeError("Expecting value", s, err.value) from None
json.decoder.JSONDecodeError: Expecting value: line 2 column 1 (char 1)

14-05-2023 13:24:07 ERROR ERROR AT CATEGORY: 11905
14-05-2023 13:24:07 ERROR ERROR AT PRODUCT: 199098905
14-05-2023 13:24:07 INFO STARTED TIME  : 12:27:04 14/05/2023
14-05-2023 13:24:07 INFO FINISHED TIME : 13:24:07 14/05/2023
14-05-2023 13:24:07 INFO EXECUTION TINE: 0:57:02.600920
14-05-2023 13:24:07 INFO NUMBER OF REQUEST HAD BEEN SENT: 6834
14-05-2023 13:29:29 INFO STARTED TIME: 13:29:29 14/05/2023
14-05-2023 13:31:30 INFO [INSERTED] Inserted 0279 Products to Category ID 11905
14-05-2023 13:32:32 INFO [INSERTED] Inserted 0121 Products to Category ID 11907
14-05-2023 13:34:26 INFO [INSERTED] Inserted 0221 Products to Category ID 11911
14-05-2023 13:34:30 INFO [INSERTED] Inserted 0010 Products to Category ID 11915
14-05-2023 13:38:28 INFO [INSERTED] Inserted 0474 Products to Category ID 8168
14-05-2023 13:38:43 INFO [INSERTED] Inserted 0041 Products to Category ID 11921
14-05-2023 13:46:07 INFO STARTED TIME  : 13:29:29 14/05/2023
14-05-2023 13:46:07 INFO FINISHED TIME : 13:46:07 14/05/2023
14-05-2023 13:46:07 INFO EXECUTION TINE: 0:16:38.636343
14-05-2023 13:46:07 INFO NUMBER OF REQUEST HAD BEEN SENT: 2016
14-05-2023 13:57:07 INFO STARTED TIME: 13:57:07 14/05/2023
14-05-2023 14:04:17 INFO [INSERTED] Inserted 0853 Products to Category ID 11923
14-05-2023 14:05:48 INFO [INSERTED] Inserted 0201 Products to Category ID 11925
14-05-2023 14:06:27 INFO [INSERTED] Inserted 0079 Products to Category ID 11929
14-05-2023 14:07:37 INFO [INSERTED] Inserted 0124 Products to Category ID 11931
14-05-2023 14:08:35 INFO [INSERTED] Inserted 0132 Products to Category ID 1633
14-05-2023 14:08:41 INFO [INSERTED] Inserted 0017 Products to Category ID 2162
14-05-2023 14:25:38 INFO [INSERTED] Inserted 2000 Products to Category ID 2340
14-05-2023 14:33:26 INFO [INSERTED] Inserted 0917 Products to Category ID 2342
14-05-2023 17:19:34 INFO STARTED TIME: 17:19:34 14/05/2023
14-05-2023 17:29:55 INFO [INSERTED] Inserted 1239 Products to Category ID 8170
14-05-2023 17:34:16 INFO [INSERTED] Inserted 0530 Products to Category ID 8171
14-05-2023 17:44:16 INFO [INSERTED] Inserted 1189 Products to Category ID 8172
14-05-2023 17:57:06 INFO [INSERTED] Inserted 1514 Products to Category ID 8305
14-05-2023 17:57:49 INFO [INSERTED] Inserted 0069 Products to Category ID 11893
14-05-2023 17:57:50 INFO [INSERTED] Inserted 0003 Products to Category ID 11895
14-05-2023 18:00:02 INFO [INSERTED] Inserted 0266 Products to Category ID 11897
14-05-2023 18:00:42 INFO [INSERTED] Inserted 0073 Products to Category ID 11899
14-05-2023 18:01:07 INFO [INSERTED] Inserted 0063 Products to Category ID 11901
14-05-2023 18:10:21 INFO [INSERTED] Inserted 1105 Products to Category ID 11857
14-05-2023 18:16:47 INFO [INSERTED] Inserted 0745 Products to Category ID 11859
14-05-2023 18:21:20 INFO [INSERTED] Inserted 0561 Products to Category ID 11861
14-05-2023 18:22:50 INFO [INSERTED] Inserted 0149 Products to Category ID 11863
14-05-2023 18:24:15 INFO [INSERTED] Inserted 0198 Products to Category ID 11865
14-05-2023 18:25:38 INFO [INSERTED] Inserted 0141 Products to Category ID 11867
14-05-2023 18:32:46 INFO [INSERTED] Inserted 0848 Products to Category ID 11869
14-05-2023 18:35:10 INFO [INSERTED] Inserted 0305 Products to Category ID 11871
14-05-2023 21:32:02 INFO STARTED TIME  : 17:19:34 14/05/2023
14-05-2023 21:32:02 INFO FINISHED TIME : 21:32:02 14/05/2023
14-05-2023 21:32:02 INFO EXECUTION TINE: 4:12:28.228019
14-05-2023 21:32:02 INFO NUMBER OF REQUEST HAD BEEN SENT: 9904
14-05-2023 21:32:52 INFO STARTED TIME: 21:32:52 14/05/2023
14-05-2023 21:40:59 INFO [INSERTED] Inserted 0962 Products to Category ID 11873
14-05-2023 21:45:23 INFO [INSERTED] Inserted 0521 Products to Category ID 11875
14-05-2023 21:47:28 INFO [INSERTED] Inserted 0262 Products to Category ID 11877
14-05-2023 21:51:14 INFO [INSERTED] Inserted 0442 Products to Category ID 11879
14-05-2023 21:54:23 INFO [INSERTED] Inserted 0384 Products to Category ID 11881
14-05-2023 22:00:08 INFO [INSERTED] Inserted 0679 Products to Category ID 11845
14-05-2023 22:02:54 INFO [INSERTED] Inserted 0318 Products to Category ID 11847
14-05-2023 22:04:25 INFO [INSERTED] Inserted 0185 Products to Category ID 11849
14-05-2023 22:05:27 INFO [INSERTED] Inserted 0130 Products to Category ID 11851
14-05-2023 22:06:12 INFO [INSERTED] Inserted 0062 Products to Category ID 11853
14-05-2023 22:06:25 INFO [INSERTED] Inserted 0032 Products to Category ID 11855
14-05-2023 22:11:59 INFO [INSERTED] Inserted 0654 Products to Category ID 11883
14-05-2023 22:17:31 INFO [INSERTED] Inserted 0685 Products to Category ID 11885
14-05-2023 22:18:28 INFO [INSERTED] Inserted 0122 Products to Category ID 11887
14-05-2023 22:20:16 INFO [INSERTED] Inserted 0204 Products to Category ID 11889
14-05-2023 22:22:14 INFO [INSERTED] Inserted 0230 Products to Category ID 11868
14-05-2023 22:28:29 INFO [INSERTED] Inserted 0745 Products to Category ID 8224
14-05-2023 22:42:23 INFO [INSERTED] Inserted 1639 Products to Category ID 8225
14-05-2023 22:59:11 INFO [INSERTED] Inserted 2000 Products to Category ID 8602
14-05-2023 22:59:12 INFO [INSERTED] Inserted 0001 Products to Category ID 5874
14-05-2023 23:11:14 INFO [INSERTED] Inserted 1419 Products to Category ID 1630
14-05-2023 23:13:33 INFO [INSERTED] Inserted 0284 Products to Category ID 1631
14-05-2023 23:13:35 INFO [INSERTED] Inserted 0006 Products to Category ID 8161
14-05-2023 23:22:19 INFO [INSERTED] Inserted 1008 Products to Category ID 49630
14-05-2023 23:39:07 INFO [INSERTED] Inserted 2000 Products to Category ID 49632
14-05-2023 23:56:04 INFO [INSERTED] Inserted 2000 Products to Category ID 49620
15-05-2023 00:02:28 INFO [INSERTED] Inserted 0775 Products to Category ID 49622
15-05-2023 00:05:24 INFO [INSERTED] Inserted 0343 Products to Category ID 49624
15-05-2023 00:22:22 INFO [INSERTED] Inserted 2000 Products to Category ID 49626
15-05-2023 00:23:33 ERROR Traceback (most recent call last):
  File "/home/ngkhachuy/anaconda3/lib/python3.9/site-packages/urllib3/response.py", line 761, in _update_chunk_length
    self.chunk_left = int(line, 16)
ValueError: invalid literal for int() with base 16: b''

During handling of the above exception, another exception occurred:

Traceback (most recent call last):
  File "/home/ngkhachuy/anaconda3/lib/python3.9/site-packages/urllib3/response.py", line 444, in _error_catcher
    yield
  File "/home/ngkhachuy/anaconda3/lib/python3.9/site-packages/urllib3/response.py", line 828, in read_chunked
    self._update_chunk_length()
  File "/home/ngkhachuy/anaconda3/lib/python3.9/site-packages/urllib3/response.py", line 765, in _update_chunk_length
    raise InvalidChunkLength(self, line)
urllib3.exceptions.InvalidChunkLength: InvalidChunkLength(got length b'', 0 bytes read)

During handling of the above exception, another exception occurred:

Traceback (most recent call last):
  File "/home/ngkhachuy/anaconda3/lib/python3.9/site-packages/requests/models.py", line 816, in generate
    yield from self.raw.stream(chunk_size, decode_content=True)
  File "/home/ngkhachuy/anaconda3/lib/python3.9/site-packages/urllib3/response.py", line 624, in stream
    for line in self.read_chunked(amt, decode_content=decode_content):
  File "/home/ngkhachuy/anaconda3/lib/python3.9/site-packages/urllib3/response.py", line 857, in read_chunked
    self._original_response.close()
  File "/home/ngkhachuy/anaconda3/lib/python3.9/contextlib.py", line 137, in __exit__
    self.gen.throw(typ, value, traceback)
  File "/home/ngkhachuy/anaconda3/lib/python3.9/site-packages/urllib3/response.py", line 461, in _error_catcher
    raise ProtocolError("Connection broken: %r" % e, e)
urllib3.exceptions.ProtocolError: ("Connection broken: InvalidChunkLength(got length b'', 0 bytes read)", InvalidChunkLength(got length b'', 0 bytes read))

During handling of the above exception, another exception occurred:

Traceback (most recent call last):
  File "/home/ngkhachuy/PROJECT/DEC_PJ4_TIKI.VN/get_product_API.py", line 85, in <module>
    prod_detail = COMMON.send_get_request(PRODUCT_DETAIL_API % p_id)
  File "/home/ngkhachuy/PROJECT/DEC_PJ4_TIKI.VN/COMMON.py", line 25, in send_get_request
    res_tmp = requests.get(url, headers={"user-agent":
  File "/home/ngkhachuy/anaconda3/lib/python3.9/site-packages/requests/api.py", line 73, in get
    return request("get", url, params=params, **kwargs)
  File "/home/ngkhachuy/anaconda3/lib/python3.9/site-packages/requests/api.py", line 59, in request
    return session.request(method=method, url=url, **kwargs)
  File "/home/ngkhachuy/anaconda3/lib/python3.9/site-packages/requests/sessions.py", line 587, in request
    resp = self.send(prep, **send_kwargs)
  File "/home/ngkhachuy/anaconda3/lib/python3.9/site-packages/requests/sessions.py", line 745, in send
    r.content
  File "/home/ngkhachuy/anaconda3/lib/python3.9/site-packages/requests/models.py", line 899, in content
    self._content = b"".join(self.iter_content(CONTENT_CHUNK_SIZE)) or b""
  File "/home/ngkhachuy/anaconda3/lib/python3.9/site-packages/requests/models.py", line 818, in generate
    raise ChunkedEncodingError(e)
requests.exceptions.ChunkedEncodingError: ("Connection broken: InvalidChunkLength(got length b'', 0 bytes read)", InvalidChunkLength(got length b'', 0 bytes read))

15-05-2023 00:23:33 ERROR ERROR AT CATEGORY: 49628
15-05-2023 00:23:33 ERROR ERROR AT PRODUCT: 97951238
15-05-2023 00:23:33 INFO STARTED TIME  : 21:32:52 14/05/2023
15-05-2023 00:23:33 INFO FINISHED TIME : 00:23:33 15/05/2023
15-05-2023 00:23:33 INFO EXECUTION TINE: 2:50:41.429901
15-05-2023 00:23:33 INFO NUMBER OF REQUEST HAD BEEN SENT: 20453
15-05-2023 06:02:46 INFO STARTED TIME: 06:02:46 15/05/2023
15-05-2023 06:05:03 INFO [INSERTED] Inserted 0282 Products to Category ID 49628
15-05-2023 06:16:21 INFO [INSERTED] Inserted 1326 Products to Category ID 49634
15-05-2023 06:19:59 INFO [INSERTED] Inserted 0425 Products to Category ID 49636
15-05-2023 06:32:26 INFO [INSERTED] Inserted 1507 Products to Category ID 10383
15-05-2023 06:49:23 INFO [INSERTED] Inserted 2000 Products to Category ID 10384
15-05-2023 06:50:33 INFO [INSERTED] Inserted 0146 Products to Category ID 49638
15-05-2023 06:55:13 INFO [INSERTED] Inserted 0532 Products to Category ID 49640
15-05-2023 06:57:37 INFO [INSERTED] Inserted 0288 Products to Category ID 49642
15-05-2023 07:04:54 INFO [INSERTED] Inserted 0851 Products to Category ID 49644
15-05-2023 07:07:01 INFO [INSERTED] Inserted 0260 Products to Category ID 49646
15-05-2023 07:17:56 INFO [INSERTED] Inserted 1296 Products to Category ID 49648
15-05-2023 07:18:07 INFO STARTED TIME  : 06:02:46 15/05/2023
15-05-2023 07:18:07 INFO FINISHED TIME : 07:18:07 15/05/2023
15-05-2023 07:18:07 INFO EXECUTION TINE: 1:15:21.475749
15-05-2023 07:18:07 INFO NUMBER OF REQUEST HAD BEEN SENT: 9035
15-05-2023 08:16:19 INFO STARTED TIME: 08:16:19 15/05/2023
15-05-2023 08:17:36 INFO STARTED TIME  : 08:16:19 15/05/2023
15-05-2023 08:17:36 INFO FINISHED TIME : 08:17:36 15/05/2023
15-05-2023 08:17:36 INFO EXECUTION TINE: 0:01:17.535535
15-05-2023 08:17:36 INFO NUMBER OF REQUEST HAD BEEN SENT: 142
15-05-2023 08:19:35 INFO STARTED TIME: 08:19:35 15/05/2023
15-05-2023 08:21:11 ERROR Traceback (most recent call last):
  File "/home/ngkhachuy/PROJECT/DEC_PJ4_TIKI.VN/get_product_API.py", line 85, in <module>
    prod_detail = COMMON.send_get_request(PRODUCT_DETAIL_API % p_id)
  File "/home/ngkhachuy/PROJECT/DEC_PJ4_TIKI.VN/COMMON.py", line 33, in send_get_request
    print("----- Sleep %is -----" % 5 + count)
TypeError: can only concatenate str (not "int") to str

15-05-2023 08:21:11 ERROR ERROR AT CATEGORY: 1008
15-05-2023 08:21:11 ERROR ERROR AT PRODUCT: 194410214
15-05-2023 08:21:11 INFO STARTED TIME  : 08:19:35 15/05/2023
15-05-2023 08:21:11 INFO FINISHED TIME : 08:21:11 15/05/2023
15-05-2023 08:21:11 INFO EXECUTION TINE: 0:01:35.930164
15-05-2023 08:21:11 INFO NUMBER OF REQUEST HAD BEEN SENT: 228
15-05-2023 08:21:54 INFO STARTED TIME: 08:21:54 15/05/2023
15-05-2023 08:31:32 INFO [INSERTED] Inserted 1163 Products to Category ID 1008
15-05-2023 08:35:08 INFO [INSERTED] Inserted 0431 Products to Category ID 49564
15-05-2023 08:48:42 INFO [INSERTED] Inserted 1602 Products to Category ID 49566
15-05-2023 08:48:45 INFO STARTED TIME  : 08:21:54 15/05/2023
15-05-2023 08:48:45 INFO FINISHED TIME : 08:48:45 15/05/2023
15-05-2023 08:48:45 INFO EXECUTION TINE: 0:26:51.894665
15-05-2023 08:48:45 INFO NUMBER OF REQUEST HAD BEEN SENT: 3238
15-05-2023 08:55:10 INFO STARTED TIME: 08:55:10 15/05/2023
15-05-2023 08:55:50 INFO [INSERTED] Inserted 0100 Products to Category ID 49568
15-05-2023 08:59:53 INFO STARTED TIME  : 08:55:10 15/05/2023
15-05-2023 08:59:53 INFO FINISHED TIME : 08:59:53 15/05/2023
15-05-2023 08:59:53 INFO EXECUTION TINE: 0:04:43.303758
15-05-2023 08:59:53 INFO NUMBER OF REQUEST HAD BEEN SENT: 584
15-05-2023 09:02:20 INFO STARTED TIME: 09:02:20 15/05/2023
15-05-2023 09:19:03 INFO [INSERTED] Inserted 2000 Products to Category ID 49552
15-05-2023 09:20:02 INFO STARTED TIME  : 09:02:20 15/05/2023
15-05-2023 09:20:02 INFO FINISHED TIME : 09:20:02 15/05/2023
15-05-2023 09:20:02 INFO EXECUTION TINE: 0:17:42.028827
15-05-2023 09:20:02 INFO NUMBER OF REQUEST HAD BEEN SENT: 2141
15-05-2023 09:20:34 INFO STARTED TIME: 09:20:34 15/05/2023
15-05-2023 09:24:06 INFO STARTED TIME  : 09:20:34 15/05/2023
15-05-2023 09:24:06 INFO FINISHED TIME : 09:24:06 15/05/2023
15-05-2023 09:24:06 INFO EXECUTION TINE: 0:03:32.143576
15-05-2023 09:24:06 INFO NUMBER OF REQUEST HAD BEEN SENT: 460
15-05-2023 09:28:53 INFO STARTED TIME: 09:28:53 15/05/2023
15-05-2023 09:33:06 INFO [INSERTED] Inserted 0519 Products to Category ID 49554
15-05-2023 10:30:58 INFO STARTED TIME: 10:30:58 15/05/2023
15-05-2023 10:30:59 ERROR Traceback (most recent call last):
  File "/home/ngkhachuy/PROJECT/DEC_PJ4_TIKI.VN/get_product_API.py", line 141, in <module>
    LIST_PRODUCT.append(PRODUCT(p_id, p_name, p_short_description, p_description, p_url, p_rating,
TypeError: __init__() takes 11 positional arguments but 13 were given

15-05-2023 10:30:59 ERROR ERROR AT CATEGORY: 49560
15-05-2023 10:30:59 ERROR ERROR AT PRODUCT: 179877586
15-05-2023 10:30:59 INFO STARTED TIME  : 10:30:58 15/05/2023
15-05-2023 10:30:59 INFO FINISHED TIME : 10:30:59 15/05/2023
15-05-2023 10:30:59 INFO EXECUTION TINE: 0:00:01.036365
15-05-2023 10:30:59 INFO NUMBER OF REQUEST HAD BEEN SENT: 2
15-05-2023 10:35:21 INFO STARTED TIME: 10:35:21 15/05/2023
15-05-2023 10:36:29 INFO [INSERTED] Inserted 0182 Products to Category ID 49560
15-05-2023 10:39:13 INFO [INSERTED] Inserted 0291 Products to Category ID 49562
15-05-2023 10:39:41 INFO [INSERTED] Inserted 0070 Products to Category ID 49582
15-05-2023 10:41:06 INFO STARTED TIME  : 10:35:21 15/05/2023
15-05-2023 10:41:06 INFO FINISHED TIME : 10:41:06 15/05/2023
15-05-2023 10:41:06 INFO EXECUTION TINE: 0:05:44.825583
15-05-2023 10:41:06 INFO NUMBER OF REQUEST HAD BEEN SENT: 703
15-05-2023 10:43:01 INFO STARTED TIME: 10:43:01 15/05/2023
15-05-2023 10:46:52 INFO [INSERTED] Inserted 0475 Products to Category ID 49584
15-05-2023 10:48:25 INFO [INSERTED] Inserted 0178 Products to Category ID 49586
15-05-2023 10:55:45 INFO [INSERTED] Inserted 0882 Products to Category ID 49588
15-05-2023 13:28:16 INFO STARTED TIME  : 10:43:01 15/05/2023
15-05-2023 13:28:16 INFO FINISHED TIME : 13:28:16 15/05/2023
15-05-2023 13:28:16 INFO EXECUTION TINE: 2:45:15.146255
15-05-2023 13:28:16 INFO NUMBER OF REQUEST HAD BEEN SENT: 2750
15-05-2023 13:29:09 INFO STARTED TIME: 13:29:09 15/05/2023
15-05-2023 13:42:16 INFO [INSERTED] Inserted 1556 Products to Category ID 49542
15-05-2023 13:43:34 INFO STARTED TIME  : 13:29:09 15/05/2023
15-05-2023 13:43:34 INFO FINISHED TIME : 13:43:34 15/05/2023
15-05-2023 13:43:34 INFO EXECUTION TINE: 0:14:25.323315
15-05-2023 13:43:34 INFO NUMBER OF REQUEST HAD BEEN SENT: 1739
15-05-2023 13:49:45 INFO STARTED TIME: 13:49:45 15/05/2023
15-05-2023 13:52:57 INFO [INSERTED] Inserted 0365 Products to Category ID 49544
15-05-2023 14:19:13 INFO STARTED TIME: 14:19:13 15/05/2023
15-05-2023 14:33:41 INFO [INSERTED] Inserted 1736 Products to Category ID 49546
15-05-2023 14:50:34 INFO [INSERTED] Inserted 2000 Products to Category ID 49548
15-05-2023 14:53:05 INFO [INSERTED] Inserted 0284 Products to Category ID 49550
15-05-2023 15:04:28 INFO [INSERTED] Inserted 1391 Products to Category ID 49590
15-05-2023 15:09:04 ERROR [TIMEOUT] Restart script!
15-05-2023 15:09:05 INFO STARTED TIME: 15:09:05 15/05/2023
15-05-2023 15:09:05 ERROR Traceback (most recent call last):
  File "/home/ngkhachuy/anaconda3/lib/python3.9/site-packages/urllib3/connection.py", line 174, in _new_conn
    conn = connection.create_connection(
  File "/home/ngkhachuy/anaconda3/lib/python3.9/site-packages/urllib3/util/connection.py", line 72, in create_connection
    for res in socket.getaddrinfo(host, port, family, socket.SOCK_STREAM):
  File "/home/ngkhachuy/anaconda3/lib/python3.9/socket.py", line 954, in getaddrinfo
    for res in _socket.getaddrinfo(host, port, family, type, proto, flags):
socket.gaierror: [Errno -3] Temporary failure in name resolution

During handling of the above exception, another exception occurred:

Traceback (most recent call last):
  File "/home/ngkhachuy/anaconda3/lib/python3.9/site-packages/urllib3/connectionpool.py", line 703, in urlopen
    httplib_response = self._make_request(
  File "/home/ngkhachuy/anaconda3/lib/python3.9/site-packages/urllib3/connectionpool.py", line 386, in _make_request
    self._validate_conn(conn)
  File "/home/ngkhachuy/anaconda3/lib/python3.9/site-packages/urllib3/connectionpool.py", line 1042, in _validate_conn
    conn.connect()
  File "/home/ngkhachuy/anaconda3/lib/python3.9/site-packages/urllib3/connection.py", line 358, in connect
    self.sock = conn = self._new_conn()
  File "/home/ngkhachuy/anaconda3/lib/python3.9/site-packages/urllib3/connection.py", line 186, in _new_conn
    raise NewConnectionError(
urllib3.exceptions.NewConnectionError: <urllib3.connection.HTTPSConnection object at 0x7f6b2921eb50>: Failed to establish a new connection: [Errno -3] Temporary failure in name resolution

During handling of the above exception, another exception occurred:

Traceback (most recent call last):
  File "/home/ngkhachuy/anaconda3/lib/python3.9/site-packages/requests/adapters.py", line 489, in send
    resp = conn.urlopen(
  File "/home/ngkhachuy/anaconda3/lib/python3.9/site-packages/urllib3/connectionpool.py", line 787, in urlopen
    retries = retries.increment(
  File "/home/ngkhachuy/anaconda3/lib/python3.9/site-packages/urllib3/util/retry.py", line 592, in increment
    raise MaxRetryError(_pool, url, error or ResponseError(cause))
urllib3.exceptions.MaxRetryError: HTTPSConnectionPool(host='tiki.vn', port=443): Max retries exceeded with url: /api/v2/products?limit=100&include=advertisement&aggregations=1&category=49592&page=1 (Caused by NewConnectionError('<urllib3.connection.HTTPSConnection object at 0x7f6b2921eb50>: Failed to establish a new connection: [Errno -3] Temporary failure in name resolution'))

During handling of the above exception, another exception occurred:

Traceback (most recent call last):
  File "/home/ngkhachuy/PROJECT/DEC_PJ4_TIKI.VN/get_product_API.py", line 72, in <module>
    prod_list = COMMON.send_get_request(LIST_PRODUCT_API % (cat_id, page))
  File "/home/ngkhachuy/PROJECT/DEC_PJ4_TIKI.VN/COMMON.py", line 24, in send_get_request
    res_tmp = requests.get(url, headers={"user-agent":
  File "/home/ngkhachuy/anaconda3/lib/python3.9/site-packages/requests/api.py", line 73, in get
    return request("get", url, params=params, **kwargs)
  File "/home/ngkhachuy/anaconda3/lib/python3.9/site-packages/requests/api.py", line 59, in request
    return session.request(method=method, url=url, **kwargs)
  File "/home/ngkhachuy/anaconda3/lib/python3.9/site-packages/requests/sessions.py", line 587, in request
    resp = self.send(prep, **send_kwargs)
  File "/home/ngkhachuy/anaconda3/lib/python3.9/site-packages/requests/sessions.py", line 701, in send
    r = adapter.send(request, **kwargs)
  File "/home/ngkhachuy/anaconda3/lib/python3.9/site-packages/requests/adapters.py", line 565, in send
    raise ConnectionError(e, request=request)
requests.exceptions.ConnectionError: HTTPSConnectionPool(host='tiki.vn', port=443): Max retries exceeded with url: /api/v2/products?limit=100&include=advertisement&aggregations=1&category=49592&page=1 (Caused by NewConnectionError('<urllib3.connection.HTTPSConnection object at 0x7f6b2921eb50>: Failed to establish a new connection: [Errno -3] Temporary failure in name resolution'))

15-05-2023 15:09:05 ERROR ERROR AT CATEGORY: 49592
15-05-2023 15:09:05 ERROR ERROR AT PRODUCT: 
15-05-2023 15:09:05 ERROR [ERROR] Restart script!
15-05-2023 15:09:05 INFO STARTED TIME: 15:09:05 15/05/2023
15-05-2023 15:09:05 ERROR Traceback (most recent call last):
  File "/home/ngkhachuy/anaconda3/lib/python3.9/site-packages/urllib3/connection.py", line 174, in _new_conn
    conn = connection.create_connection(
  File "/home/ngkhachuy/anaconda3/lib/python3.9/site-packages/urllib3/util/connection.py", line 72, in create_connection
    for res in socket.getaddrinfo(host, port, family, socket.SOCK_STREAM):
  File "/home/ngkhachuy/anaconda3/lib/python3.9/socket.py", line 954, in getaddrinfo
    for res in _socket.getaddrinfo(host, port, family, type, proto, flags):
socket.gaierror: [Errno -3] Temporary failure in name resolution

During handling of the above exception, another exception occurred:

Traceback (most recent call last):
  File "/home/ngkhachuy/anaconda3/lib/python3.9/site-packages/urllib3/connectionpool.py", line 703, in urlopen
    httplib_response = self._make_request(
  File "/home/ngkhachuy/anaconda3/lib/python3.9/site-packages/urllib3/connectionpool.py", line 386, in _make_request
    self._validate_conn(conn)
  File "/home/ngkhachuy/anaconda3/lib/python3.9/site-packages/urllib3/connectionpool.py", line 1042, in _validate_conn
    conn.connect()
  File "/home/ngkhachuy/anaconda3/lib/python3.9/site-packages/urllib3/connection.py", line 358, in connect
    self.sock = conn = self._new_conn()
  File "/home/ngkhachuy/anaconda3/lib/python3.9/site-packages/urllib3/connection.py", line 186, in _new_conn
    raise NewConnectionError(
urllib3.exceptions.NewConnectionError: <urllib3.connection.HTTPSConnection object at 0x7f4380de77c0>: Failed to establish a new connection: [Errno -3] Temporary failure in name resolution

During handling of the above exception, another exception occurred:

Traceback (most recent call last):
  File "/home/ngkhachuy/anaconda3/lib/python3.9/site-packages/requests/adapters.py", line 489, in send
    resp = conn.urlopen(
  File "/home/ngkhachuy/anaconda3/lib/python3.9/site-packages/urllib3/connectionpool.py", line 787, in urlopen
    retries = retries.increment(
  File "/home/ngkhachuy/anaconda3/lib/python3.9/site-packages/urllib3/util/retry.py", line 592, in increment
    raise MaxRetryError(_pool, url, error or ResponseError(cause))
urllib3.exceptions.MaxRetryError: HTTPSConnectionPool(host='tiki.vn', port=443): Max retries exceeded with url: /api/v2/products?limit=100&include=advertisement&aggregations=1&category=49592&page=1 (Caused by NewConnectionError('<urllib3.connection.HTTPSConnection object at 0x7f4380de77c0>: Failed to establish a new connection: [Errno -3] Temporary failure in name resolution'))

During handling of the above exception, another exception occurred:

Traceback (most recent call last):
  File "/home/ngkhachuy/PROJECT/DEC_PJ4_TIKI.VN/get_product_API.py", line 72, in <module>
    prod_list = COMMON.send_get_request(LIST_PRODUCT_API % (cat_id, page))
  File "/home/ngkhachuy/PROJECT/DEC_PJ4_TIKI.VN/COMMON.py", line 24, in send_get_request
    res_tmp = requests.get(url, headers={"user-agent":
  File "/home/ngkhachuy/anaconda3/lib/python3.9/site-packages/requests/api.py", line 73, in get
    return request("get", url, params=params, **kwargs)
  File "/home/ngkhachuy/anaconda3/lib/python3.9/site-packages/requests/api.py", line 59, in request
    return session.request(method=method, url=url, **kwargs)
  File "/home/ngkhachuy/anaconda3/lib/python3.9/site-packages/requests/sessions.py", line 587, in request
    resp = self.send(prep, **send_kwargs)
  File "/home/ngkhachuy/anaconda3/lib/python3.9/site-packages/requests/sessions.py", line 701, in send
    r = adapter.send(request, **kwargs)
  File "/home/ngkhachuy/anaconda3/lib/python3.9/site-packages/requests/adapters.py", line 565, in send
    raise ConnectionError(e, request=request)
requests.exceptions.ConnectionError: HTTPSConnectionPool(host='tiki.vn', port=443): Max retries exceeded with url: /api/v2/products?limit=100&include=advertisement&aggregations=1&category=49592&page=1 (Caused by NewConnectionError('<urllib3.connection.HTTPSConnection object at 0x7f4380de77c0>: Failed to establish a new connection: [Errno -3] Temporary failure in name resolution'))

15-05-2023 15:09:06 ERROR ERROR AT CATEGORY: 49592
15-05-2023 15:09:06 ERROR ERROR AT PRODUCT: 
15-05-2023 15:09:06 ERROR [ERROR] Restart script!
15-05-2023 15:09:06 INFO STARTED TIME: 15:09:06 15/05/2023
15-05-2023 15:09:06 ERROR Traceback (most recent call last):
  File "/home/ngkhachuy/anaconda3/lib/python3.9/site-packages/urllib3/connection.py", line 174, in _new_conn
    conn = connection.create_connection(
  File "/home/ngkhachuy/anaconda3/lib/python3.9/site-packages/urllib3/util/connection.py", line 72, in create_connection
    for res in socket.getaddrinfo(host, port, family, socket.SOCK_STREAM):
  File "/home/ngkhachuy/anaconda3/lib/python3.9/socket.py", line 954, in getaddrinfo
    for res in _socket.getaddrinfo(host, port, family, type, proto, flags):
socket.gaierror: [Errno -3] Temporary failure in name resolution

During handling of the above exception, another exception occurred:

Traceback (most recent call last):
  File "/home/ngkhachuy/anaconda3/lib/python3.9/site-packages/urllib3/connectionpool.py", line 703, in urlopen
    httplib_response = self._make_request(
  File "/home/ngkhachuy/anaconda3/lib/python3.9/site-packages/urllib3/connectionpool.py", line 386, in _make_request
    self._validate_conn(conn)
  File "/home/ngkhachuy/anaconda3/lib/python3.9/site-packages/urllib3/connectionpool.py", line 1042, in _validate_conn
    conn.connect()
  File "/home/ngkhachuy/anaconda3/lib/python3.9/site-packages/urllib3/connection.py", line 358, in connect
    self.sock = conn = self._new_conn()
  File "/home/ngkhachuy/anaconda3/lib/python3.9/site-packages/urllib3/connection.py", line 186, in _new_conn
    raise NewConnectionError(
urllib3.exceptions.NewConnectionError: <urllib3.connection.HTTPSConnection object at 0x7f116a1b40a0>: Failed to establish a new connection: [Errno -3] Temporary failure in name resolution

During handling of the above exception, another exception occurred:

Traceback (most recent call last):
  File "/home/ngkhachuy/anaconda3/lib/python3.9/site-packages/requests/adapters.py", line 489, in send
    resp = conn.urlopen(
  File "/home/ngkhachuy/anaconda3/lib/python3.9/site-packages/urllib3/connectionpool.py", line 787, in urlopen
    retries = retries.increment(
  File "/home/ngkhachuy/anaconda3/lib/python3.9/site-packages/urllib3/util/retry.py", line 592, in increment
    raise MaxRetryError(_pool, url, error or ResponseError(cause))
urllib3.exceptions.MaxRetryError: HTTPSConnectionPool(host='tiki.vn', port=443): Max retries exceeded with url: /api/v2/products?limit=100&include=advertisement&aggregations=1&category=49592&page=1 (Caused by NewConnectionError('<urllib3.connection.HTTPSConnection object at 0x7f116a1b40a0>: Failed to establish a new connection: [Errno -3] Temporary failure in name resolution'))

During handling of the above exception, another exception occurred:

Traceback (most recent call last):
  File "/home/ngkhachuy/PROJECT/DEC_PJ4_TIKI.VN/get_product_API.py", line 72, in <module>
    prod_list = COMMON.send_get_request(LIST_PRODUCT_API % (cat_id, page))
  File "/home/ngkhachuy/PROJECT/DEC_PJ4_TIKI.VN/COMMON.py", line 24, in send_get_request
    res_tmp = requests.get(url, headers={"user-agent":
  File "/home/ngkhachuy/anaconda3/lib/python3.9/site-packages/requests/api.py", line 73, in get
    return request("get", url, params=params, **kwargs)
  File "/home/ngkhachuy/anaconda3/lib/python3.9/site-packages/requests/api.py", line 59, in request
    return session.request(method=method, url=url, **kwargs)
  File "/home/ngkhachuy/anaconda3/lib/python3.9/site-packages/requests/sessions.py", line 587, in request
    resp = self.send(prep, **send_kwargs)
  File "/home/ngkhachuy/anaconda3/lib/python3.9/site-packages/requests/sessions.py", line 701, in send
    r = adapter.send(request, **kwargs)
  File "/home/ngkhachuy/anaconda3/lib/python3.9/site-packages/requests/adapters.py", line 565, in send
    raise ConnectionError(e, request=request)
requests.exceptions.ConnectionError: HTTPSConnectionPool(host='tiki.vn', port=443): Max retries exceeded with url: /api/v2/products?limit=100&include=advertisement&aggregations=1&category=49592&page=1 (Caused by NewConnectionError('<urllib3.connection.HTTPSConnection object at 0x7f116a1b40a0>: Failed to establish a new connection: [Errno -3] Temporary failure in name resolution'))

15-05-2023 15:09:06 ERROR ERROR AT CATEGORY: 49592
15-05-2023 15:09:06 ERROR ERROR AT PRODUCT: 
15-05-2023 15:09:06 ERROR [ERROR] Restart script!
15-05-2023 15:09:07 INFO STARTED TIME: 15:09:07 15/05/2023
15-05-2023 15:09:07 ERROR Traceback (most recent call last):
  File "/home/ngkhachuy/anaconda3/lib/python3.9/site-packages/urllib3/connection.py", line 174, in _new_conn
    conn = connection.create_connection(
  File "/home/ngkhachuy/anaconda3/lib/python3.9/site-packages/urllib3/util/connection.py", line 72, in create_connection
    for res in socket.getaddrinfo(host, port, family, socket.SOCK_STREAM):
  File "/home/ngkhachuy/anaconda3/lib/python3.9/socket.py", line 954, in getaddrinfo
    for res in _socket.getaddrinfo(host, port, family, type, proto, flags):
socket.gaierror: [Errno -3] Temporary failure in name resolution

During handling of the above exception, another exception occurred:

Traceback (most recent call last):
  File "/home/ngkhachuy/anaconda3/lib/python3.9/site-packages/urllib3/connectionpool.py", line 703, in urlopen
    httplib_response = self._make_request(
  File "/home/ngkhachuy/anaconda3/lib/python3.9/site-packages/urllib3/connectionpool.py", line 386, in _make_request
    self._validate_conn(conn)
  File "/home/ngkhachuy/anaconda3/lib/python3.9/site-packages/urllib3/connectionpool.py", line 1042, in _validate_conn
    conn.connect()
  File "/home/ngkhachuy/anaconda3/lib/python3.9/site-packages/urllib3/connection.py", line 358, in connect
    self.sock = conn = self._new_conn()
  File "/home/ngkhachuy/anaconda3/lib/python3.9/site-packages/urllib3/connection.py", line 186, in _new_conn
    raise NewConnectionError(
urllib3.exceptions.NewConnectionError: <urllib3.connection.HTTPSConnection object at 0x7fc762254970>: Failed to establish a new connection: [Errno -3] Temporary failure in name resolution

During handling of the above exception, another exception occurred:

Traceback (most recent call last):
  File "/home/ngkhachuy/anaconda3/lib/python3.9/site-packages/requests/adapters.py", line 489, in send
    resp = conn.urlopen(
  File "/home/ngkhachuy/anaconda3/lib/python3.9/site-packages/urllib3/connectionpool.py", line 787, in urlopen
    retries = retries.increment(
  File "/home/ngkhachuy/anaconda3/lib/python3.9/site-packages/urllib3/util/retry.py", line 592, in increment
    raise MaxRetryError(_pool, url, error or ResponseError(cause))
urllib3.exceptions.MaxRetryError: HTTPSConnectionPool(host='tiki.vn', port=443): Max retries exceeded with url: /api/v2/products?limit=100&include=advertisement&aggregations=1&category=49592&page=1 (Caused by NewConnectionError('<urllib3.connection.HTTPSConnection object at 0x7fc762254970>: Failed to establish a new connection: [Errno -3] Temporary failure in name resolution'))

During handling of the above exception, another exception occurred:

Traceback (most recent call last):
  File "/home/ngkhachuy/PROJECT/DEC_PJ4_TIKI.VN/get_product_API.py", line 72, in <module>
    prod_list = COMMON.send_get_request(LIST_PRODUCT_API % (cat_id, page))
  File "/home/ngkhachuy/PROJECT/DEC_PJ4_TIKI.VN/COMMON.py", line 24, in send_get_request
    res_tmp = requests.get(url, headers={"user-agent":
  File "/home/ngkhachuy/anaconda3/lib/python3.9/site-packages/requests/api.py", line 73, in get
    return request("get", url, params=params, **kwargs)
  File "/home/ngkhachuy/anaconda3/lib/python3.9/site-packages/requests/api.py", line 59, in request
    return session.request(method=method, url=url, **kwargs)
  File "/home/ngkhachuy/anaconda3/lib/python3.9/site-packages/requests/sessions.py", line 587, in request
    resp = self.send(prep, **send_kwargs)
  File "/home/ngkhachuy/anaconda3/lib/python3.9/site-packages/requests/sessions.py", line 701, in send
    r = adapter.send(request, **kwargs)
  File "/home/ngkhachuy/anaconda3/lib/python3.9/site-packages/requests/adapters.py", line 565, in send
    raise ConnectionError(e, request=request)
requests.exceptions.ConnectionError: HTTPSConnectionPool(host='tiki.vn', port=443): Max retries exceeded with url: /api/v2/products?limit=100&include=advertisement&aggregations=1&category=49592&page=1 (Caused by NewConnectionError('<urllib3.connection.HTTPSConnection object at 0x7fc762254970>: Failed to establish a new connection: [Errno -3] Temporary failure in name resolution'))

15-05-2023 15:09:07 ERROR ERROR AT CATEGORY: 49592
15-05-2023 15:09:07 ERROR ERROR AT PRODUCT: 
15-05-2023 15:09:07 ERROR [ERROR] Restart script!
15-05-2023 15:09:08 INFO STARTED TIME: 15:09:08 15/05/2023
15-05-2023 15:09:08 ERROR Traceback (most recent call last):
  File "/home/ngkhachuy/anaconda3/lib/python3.9/site-packages/urllib3/connection.py", line 174, in _new_conn
    conn = connection.create_connection(
  File "/home/ngkhachuy/anaconda3/lib/python3.9/site-packages/urllib3/util/connection.py", line 72, in create_connection
    for res in socket.getaddrinfo(host, port, family, socket.SOCK_STREAM):
  File "/home/ngkhachuy/anaconda3/lib/python3.9/socket.py", line 954, in getaddrinfo
    for res in _socket.getaddrinfo(host, port, family, type, proto, flags):
socket.gaierror: [Errno -3] Temporary failure in name resolution

During handling of the above exception, another exception occurred:

Traceback (most recent call last):
  File "/home/ngkhachuy/anaconda3/lib/python3.9/site-packages/urllib3/connectionpool.py", line 703, in urlopen
    httplib_response = self._make_request(
  File "/home/ngkhachuy/anaconda3/lib/python3.9/site-packages/urllib3/connectionpool.py", line 386, in _make_request
    self._validate_conn(conn)
  File "/home/ngkhachuy/anaconda3/lib/python3.9/site-packages/urllib3/connectionpool.py", line 1042, in _validate_conn
    conn.connect()
  File "/home/ngkhachuy/anaconda3/lib/python3.9/site-packages/urllib3/connection.py", line 358, in connect
    self.sock = conn = self._new_conn()
  File "/home/ngkhachuy/anaconda3/lib/python3.9/site-packages/urllib3/connection.py", line 186, in _new_conn
    raise NewConnectionError(
urllib3.exceptions.NewConnectionError: <urllib3.connection.HTTPSConnection object at 0x7f57281148e0>: Failed to establish a new connection: [Errno -3] Temporary failure in name resolution

During handling of the above exception, another exception occurred:

Traceback (most recent call last):
  File "/home/ngkhachuy/anaconda3/lib/python3.9/site-packages/requests/adapters.py", line 489, in send
    resp = conn.urlopen(
  File "/home/ngkhachuy/anaconda3/lib/python3.9/site-packages/urllib3/connectionpool.py", line 787, in urlopen
    retries = retries.increment(
  File "/home/ngkhachuy/anaconda3/lib/python3.9/site-packages/urllib3/util/retry.py", line 592, in increment
    raise MaxRetryError(_pool, url, error or ResponseError(cause))
urllib3.exceptions.MaxRetryError: HTTPSConnectionPool(host='tiki.vn', port=443): Max retries exceeded with url: /api/v2/products?limit=100&include=advertisement&aggregations=1&category=49592&page=1 (Caused by NewConnectionError('<urllib3.connection.HTTPSConnection object at 0x7f57281148e0>: Failed to establish a new connection: [Errno -3] Temporary failure in name resolution'))

During handling of the above exception, another exception occurred:

Traceback (most recent call last):
  File "/home/ngkhachuy/PROJECT/DEC_PJ4_TIKI.VN/get_product_API.py", line 72, in <module>
    prod_list = COMMON.send_get_request(LIST_PRODUCT_API % (cat_id, page))
  File "/home/ngkhachuy/PROJECT/DEC_PJ4_TIKI.VN/COMMON.py", line 24, in send_get_request
    res_tmp = requests.get(url, headers={"user-agent":
  File "/home/ngkhachuy/anaconda3/lib/python3.9/site-packages/requests/api.py", line 73, in get
    return request("get", url, params=params, **kwargs)
  File "/home/ngkhachuy/anaconda3/lib/python3.9/site-packages/requests/api.py", line 59, in request
    return session.request(method=method, url=url, **kwargs)
  File "/home/ngkhachuy/anaconda3/lib/python3.9/site-packages/requests/sessions.py", line 587, in request
    resp = self.send(prep, **send_kwargs)
  File "/home/ngkhachuy/anaconda3/lib/python3.9/site-packages/requests/sessions.py", line 701, in send
    r = adapter.send(request, **kwargs)
  File "/home/ngkhachuy/anaconda3/lib/python3.9/site-packages/requests/adapters.py", line 565, in send
    raise ConnectionError(e, request=request)
requests.exceptions.ConnectionError: HTTPSConnectionPool(host='tiki.vn', port=443): Max retries exceeded with url: /api/v2/products?limit=100&include=advertisement&aggregations=1&category=49592&page=1 (Caused by NewConnectionError('<urllib3.connection.HTTPSConnection object at 0x7f57281148e0>: Failed to establish a new connection: [Errno -3] Temporary failure in name resolution'))

15-05-2023 15:09:08 ERROR ERROR AT CATEGORY: 49592
15-05-2023 15:09:08 ERROR ERROR AT PRODUCT: 
15-05-2023 15:09:08 ERROR [ERROR] Restart script!
15-05-2023 15:09:08 INFO STARTED TIME: 15:09:08 15/05/2023
15-05-2023 15:09:08 ERROR Traceback (most recent call last):
  File "/home/ngkhachuy/anaconda3/lib/python3.9/site-packages/urllib3/connection.py", line 174, in _new_conn
    conn = connection.create_connection(
  File "/home/ngkhachuy/anaconda3/lib/python3.9/site-packages/urllib3/util/connection.py", line 72, in create_connection
    for res in socket.getaddrinfo(host, port, family, socket.SOCK_STREAM):
  File "/home/ngkhachuy/anaconda3/lib/python3.9/socket.py", line 954, in getaddrinfo
    for res in _socket.getaddrinfo(host, port, family, type, proto, flags):
socket.gaierror: [Errno -3] Temporary failure in name resolution

During handling of the above exception, another exception occurred:

Traceback (most recent call last):
  File "/home/ngkhachuy/anaconda3/lib/python3.9/site-packages/urllib3/connectionpool.py", line 703, in urlopen
    httplib_response = self._make_request(
  File "/home/ngkhachuy/anaconda3/lib/python3.9/site-packages/urllib3/connectionpool.py", line 386, in _make_request
    self._validate_conn(conn)
  File "/home/ngkhachuy/anaconda3/lib/python3.9/site-packages/urllib3/connectionpool.py", line 1042, in _validate_conn
    conn.connect()
  File "/home/ngkhachuy/anaconda3/lib/python3.9/site-packages/urllib3/connection.py", line 358, in connect
    self.sock = conn = self._new_conn()
  File "/home/ngkhachuy/anaconda3/lib/python3.9/site-packages/urllib3/connection.py", line 186, in _new_conn
    raise NewConnectionError(
urllib3.exceptions.NewConnectionError: <urllib3.connection.HTTPSConnection object at 0x7fa9866d9d90>: Failed to establish a new connection: [Errno -3] Temporary failure in name resolution

During handling of the above exception, another exception occurred:

Traceback (most recent call last):
  File "/home/ngkhachuy/anaconda3/lib/python3.9/site-packages/requests/adapters.py", line 489, in send
    resp = conn.urlopen(
  File "/home/ngkhachuy/anaconda3/lib/python3.9/site-packages/urllib3/connectionpool.py", line 787, in urlopen
    retries = retries.increment(
  File "/home/ngkhachuy/anaconda3/lib/python3.9/site-packages/urllib3/util/retry.py", line 592, in increment
    raise MaxRetryError(_pool, url, error or ResponseError(cause))
urllib3.exceptions.MaxRetryError: HTTPSConnectionPool(host='tiki.vn', port=443): Max retries exceeded with url: /api/v2/products?limit=100&include=advertisement&aggregations=1&category=49592&page=1 (Caused by NewConnectionError('<urllib3.connection.HTTPSConnection object at 0x7fa9866d9d90>: Failed to establish a new connection: [Errno -3] Temporary failure in name resolution'))

During handling of the above exception, another exception occurred:

Traceback (most recent call last):
  File "/home/ngkhachuy/PROJECT/DEC_PJ4_TIKI.VN/get_product_API.py", line 72, in <module>
    prod_list = COMMON.send_get_request(LIST_PRODUCT_API % (cat_id, page))
  File "/home/ngkhachuy/PROJECT/DEC_PJ4_TIKI.VN/COMMON.py", line 24, in send_get_request
    res_tmp = requests.get(url, headers={"user-agent":
  File "/home/ngkhachuy/anaconda3/lib/python3.9/site-packages/requests/api.py", line 73, in get
    return request("get", url, params=params, **kwargs)
  File "/home/ngkhachuy/anaconda3/lib/python3.9/site-packages/requests/api.py", line 59, in request
    return session.request(method=method, url=url, **kwargs)
  File "/home/ngkhachuy/anaconda3/lib/python3.9/site-packages/requests/sessions.py", line 587, in request
    resp = self.send(prep, **send_kwargs)
  File "/home/ngkhachuy/anaconda3/lib/python3.9/site-packages/requests/sessions.py", line 701, in send
    r = adapter.send(request, **kwargs)
  File "/home/ngkhachuy/anaconda3/lib/python3.9/site-packages/requests/adapters.py", line 565, in send
    raise ConnectionError(e, request=request)
requests.exceptions.ConnectionError: HTTPSConnectionPool(host='tiki.vn', port=443): Max retries exceeded with url: /api/v2/products?limit=100&include=advertisement&aggregations=1&category=49592&page=1 (Caused by NewConnectionError('<urllib3.connection.HTTPSConnection object at 0x7fa9866d9d90>: Failed to establish a new connection: [Errno -3] Temporary failure in name resolution'))

15-05-2023 15:09:08 ERROR ERROR AT CATEGORY: 49592
15-05-2023 15:09:08 ERROR ERROR AT PRODUCT: 
15-05-2023 15:09:08 ERROR [ERROR] Restart script!
15-05-2023 15:09:09 INFO STARTED TIME: 15:09:09 15/05/2023
15-05-2023 15:13:58 INFO [INSERTED] Inserted 0593 Products to Category ID 49592
15-05-2023 15:24:26 INFO [INSERTED] Inserted 1257 Products to Category ID 49594
15-05-2023 15:32:20 INFO [INSERTED] Inserted 0929 Products to Category ID 49570
15-05-2023 15:35:20 INFO [INSERTED] Inserted 0363 Products to Category ID 49572
15-05-2023 15:35:31 INFO [INSERTED] Inserted 0028 Products to Category ID 49574
15-05-2023 15:46:10 INFO [INSERTED] Inserted 1241 Products to Category ID 49576
15-05-2023 16:03:03 INFO [INSERTED] Inserted 2000 Products to Category ID 49578
15-05-2023 16:16:00 INFO [INSERTED] Inserted 1540 Products to Category ID 49580
15-05-2023 16:16:03 INFO [INSERTED] Inserted 0006 Products to Category ID 20768
15-05-2023 16:32:56 INFO [INSERTED] Inserted 2000 Products to Category ID 20770
15-05-2023 16:32:58 INFO [INSERTED] Inserted 0004 Products to Category ID 20782
15-05-2023 16:33:15 INFO [INSERTED] Inserted 0045 Products to Category ID 20788
15-05-2023 16:33:33 INFO [INSERTED] Inserted 0045 Products to Category ID 20792
15-05-2023 16:33:54 INFO [INSERTED] Inserted 0028 Products to Category ID 20798
15-05-2023 16:33:56 INFO [INSERTED] Inserted 0003 Products to Category ID 20800
15-05-2023 16:33:58 INFO [INSERTED] Inserted 0005 Products to Category ID 20806
15-05-2023 16:34:15 INFO [INSERTED] Inserted 0043 Products to Category ID 20808
15-05-2023 16:34:18 INFO [INSERTED] Inserted 0007 Products to Category ID 20810
15-05-2023 16:34:34 INFO [INSERTED] Inserted 0041 Products to Category ID 20826
15-05-2023 16:34:54 INFO [INSERTED] Inserted 0028 Products to Category ID 20830
15-05-2023 16:39:08 INFO STARTED TIME  : 15:09:09 15/05/2023
15-05-2023 16:39:08 INFO FINISHED TIME : 16:39:08 15/05/2023
15-05-2023 16:39:08 INFO EXECUTION TINE: 1:29:58.582506
15-05-2023 16:39:08 INFO NUMBER OF REQUEST HAD BEEN SENT: 10840
15-05-2023 17:02:21 INFO STARTED TIME: 17:02:21 15/05/2023
15-05-2023 17:10:30 INFO [INSERTED] Inserted 0967 Products to Category ID 20832
15-05-2023 17:27:27 INFO [INSERTED] Inserted 2000 Products to Category ID 20836
15-05-2023 17:35:31 INFO [INSERTED] Inserted 0962 Products to Category ID 20838
15-05-2023 17:52:20 INFO [INSERTED] Inserted 2000 Products to Category ID 20854
15-05-2023 17:58:14 ERROR [TIMEOUT] Restart script!
15-05-2023 17:58:14 INFO STARTED TIME: 17:58:14 15/05/2023
15-05-2023 17:58:14 ERROR Traceback (most recent call last):
  File "/home/ngkhachuy/anaconda3/lib/python3.9/site-packages/urllib3/connection.py", line 174, in _new_conn
    conn = connection.create_connection(
  File "/home/ngkhachuy/anaconda3/lib/python3.9/site-packages/urllib3/util/connection.py", line 72, in create_connection
    for res in socket.getaddrinfo(host, port, family, socket.SOCK_STREAM):
  File "/home/ngkhachuy/anaconda3/lib/python3.9/socket.py", line 954, in getaddrinfo
    for res in _socket.getaddrinfo(host, port, family, type, proto, flags):
socket.gaierror: [Errno -3] Temporary failure in name resolution

During handling of the above exception, another exception occurred:

Traceback (most recent call last):
  File "/home/ngkhachuy/anaconda3/lib/python3.9/site-packages/urllib3/connectionpool.py", line 703, in urlopen
    httplib_response = self._make_request(
  File "/home/ngkhachuy/anaconda3/lib/python3.9/site-packages/urllib3/connectionpool.py", line 386, in _make_request
    self._validate_conn(conn)
  File "/home/ngkhachuy/anaconda3/lib/python3.9/site-packages/urllib3/connectionpool.py", line 1042, in _validate_conn
    conn.connect()
  File "/home/ngkhachuy/anaconda3/lib/python3.9/site-packages/urllib3/connection.py", line 358, in connect
    self.sock = conn = self._new_conn()
  File "/home/ngkhachuy/anaconda3/lib/python3.9/site-packages/urllib3/connection.py", line 186, in _new_conn
    raise NewConnectionError(
urllib3.exceptions.NewConnectionError: <urllib3.connection.HTTPSConnection object at 0x7f3b12c91850>: Failed to establish a new connection: [Errno -3] Temporary failure in name resolution

During handling of the above exception, another exception occurred:

Traceback (most recent call last):
  File "/home/ngkhachuy/anaconda3/lib/python3.9/site-packages/requests/adapters.py", line 489, in send
    resp = conn.urlopen(
  File "/home/ngkhachuy/anaconda3/lib/python3.9/site-packages/urllib3/connectionpool.py", line 787, in urlopen
    retries = retries.increment(
  File "/home/ngkhachuy/anaconda3/lib/python3.9/site-packages/urllib3/util/retry.py", line 592, in increment
    raise MaxRetryError(_pool, url, error or ResponseError(cause))
urllib3.exceptions.MaxRetryError: HTTPSConnectionPool(host='tiki.vn', port=443): Max retries exceeded with url: /api/v2/products?limit=100&include=advertisement&aggregations=1&category=20856&page=1 (Caused by NewConnectionError('<urllib3.connection.HTTPSConnection object at 0x7f3b12c91850>: Failed to establish a new connection: [Errno -3] Temporary failure in name resolution'))

During handling of the above exception, another exception occurred:

Traceback (most recent call last):
  File "/home/ngkhachuy/PROJECT/DEC_PJ4_TIKI.VN/get_product_API.py", line 72, in <module>
    prod_list = COMMON.send_get_request(LIST_PRODUCT_API % (cat_id, page))
  File "/home/ngkhachuy/PROJECT/DEC_PJ4_TIKI.VN/COMMON.py", line 24, in send_get_request
    res_tmp = requests.get(url, headers={"user-agent":
  File "/home/ngkhachuy/anaconda3/lib/python3.9/site-packages/requests/api.py", line 73, in get
    return request("get", url, params=params, **kwargs)
  File "/home/ngkhachuy/anaconda3/lib/python3.9/site-packages/requests/api.py", line 59, in request
    return session.request(method=method, url=url, **kwargs)
  File "/home/ngkhachuy/anaconda3/lib/python3.9/site-packages/requests/sessions.py", line 587, in request
    resp = self.send(prep, **send_kwargs)
  File "/home/ngkhachuy/anaconda3/lib/python3.9/site-packages/requests/sessions.py", line 701, in send
    r = adapter.send(request, **kwargs)
  File "/home/ngkhachuy/anaconda3/lib/python3.9/site-packages/requests/adapters.py", line 565, in send
    raise ConnectionError(e, request=request)
requests.exceptions.ConnectionError: HTTPSConnectionPool(host='tiki.vn', port=443): Max retries exceeded with url: /api/v2/products?limit=100&include=advertisement&aggregations=1&category=20856&page=1 (Caused by NewConnectionError('<urllib3.connection.HTTPSConnection object at 0x7f3b12c91850>: Failed to establish a new connection: [Errno -3] Temporary failure in name resolution'))

15-05-2023 17:58:14 ERROR ERROR AT CATEGORY: 20856
15-05-2023 17:58:14 ERROR ERROR AT PRODUCT: 
15-05-2023 17:58:14 ERROR [ERROR] Restart script!
15-05-2023 17:58:14 INFO STARTED TIME: 17:58:14 15/05/2023
15-05-2023 18:06:34 INFO [INSERTED] Inserted 0991 Products to Category ID 20856
15-05-2023 18:06:50 INFO [INSERTED] Inserted 0043 Products to Category ID 20858
15-05-2023 18:07:58 INFO [INSERTED] Inserted 0114 Products to Category ID 20866
15-05-2023 18:12:44 INFO [INSERTED] Inserted 0563 Products to Category ID 20872
15-05-2023 18:22:31 ERROR Traceback (most recent call last):
  File "/home/ngkhachuy/anaconda3/lib/python3.9/site-packages/urllib3/response.py", line 761, in _update_chunk_length
    self.chunk_left = int(line, 16)
ValueError: invalid literal for int() with base 16: b''

During handling of the above exception, another exception occurred:

Traceback (most recent call last):
  File "/home/ngkhachuy/anaconda3/lib/python3.9/site-packages/urllib3/response.py", line 444, in _error_catcher
    yield
  File "/home/ngkhachuy/anaconda3/lib/python3.9/site-packages/urllib3/response.py", line 828, in read_chunked
    self._update_chunk_length()
  File "/home/ngkhachuy/anaconda3/lib/python3.9/site-packages/urllib3/response.py", line 765, in _update_chunk_length
    raise InvalidChunkLength(self, line)
urllib3.exceptions.InvalidChunkLength: InvalidChunkLength(got length b'', 0 bytes read)

During handling of the above exception, another exception occurred:

Traceback (most recent call last):
  File "/home/ngkhachuy/anaconda3/lib/python3.9/site-packages/requests/models.py", line 816, in generate
    yield from self.raw.stream(chunk_size, decode_content=True)
  File "/home/ngkhachuy/anaconda3/lib/python3.9/site-packages/urllib3/response.py", line 624, in stream
    for line in self.read_chunked(amt, decode_content=decode_content):
  File "/home/ngkhachuy/anaconda3/lib/python3.9/site-packages/urllib3/response.py", line 857, in read_chunked
    self._original_response.close()
  File "/home/ngkhachuy/anaconda3/lib/python3.9/contextlib.py", line 137, in __exit__
    self.gen.throw(typ, value, traceback)
  File "/home/ngkhachuy/anaconda3/lib/python3.9/site-packages/urllib3/response.py", line 461, in _error_catcher
    raise ProtocolError("Connection broken: %r" % e, e)
urllib3.exceptions.ProtocolError: ("Connection broken: InvalidChunkLength(got length b'', 0 bytes read)", InvalidChunkLength(got length b'', 0 bytes read))

During handling of the above exception, another exception occurred:

Traceback (most recent call last):
  File "/home/ngkhachuy/PROJECT/DEC_PJ4_TIKI.VN/get_product_API.py", line 95, in <module>
    prod_detail = COMMON.send_get_request(PRODUCT_DETAIL_API % p_id)
  File "/home/ngkhachuy/PROJECT/DEC_PJ4_TIKI.VN/COMMON.py", line 24, in send_get_request
    res_tmp = requests.get(url, headers={"user-agent":
  File "/home/ngkhachuy/anaconda3/lib/python3.9/site-packages/requests/api.py", line 73, in get
    return request("get", url, params=params, **kwargs)
  File "/home/ngkhachuy/anaconda3/lib/python3.9/site-packages/requests/api.py", line 59, in request
    return session.request(method=method, url=url, **kwargs)
  File "/home/ngkhachuy/anaconda3/lib/python3.9/site-packages/requests/sessions.py", line 587, in request
    resp = self.send(prep, **send_kwargs)
  File "/home/ngkhachuy/anaconda3/lib/python3.9/site-packages/requests/sessions.py", line 745, in send
    r.content
  File "/home/ngkhachuy/anaconda3/lib/python3.9/site-packages/requests/models.py", line 899, in content
    self._content = b"".join(self.iter_content(CONTENT_CHUNK_SIZE)) or b""
  File "/home/ngkhachuy/anaconda3/lib/python3.9/site-packages/requests/models.py", line 818, in generate
    raise ChunkedEncodingError(e)
requests.exceptions.ChunkedEncodingError: ("Connection broken: InvalidChunkLength(got length b'', 0 bytes read)", InvalidChunkLength(got length b'', 0 bytes read))

15-05-2023 18:22:31 ERROR ERROR AT CATEGORY: 20874
15-05-2023 18:22:31 ERROR ERROR AT PRODUCT: 138044904
15-05-2023 18:22:31 ERROR [ERROR] Restart script!
15-05-2023 18:22:32 INFO STARTED TIME: 18:22:32 15/05/2023
15-05-2023 18:39:08 INFO [INSERTED] Inserted 2000 Products to Category ID 20874
15-05-2023 18:45:43 INFO [INSERTED] Inserted 0782 Products to Category ID 20886
15-05-2023 19:02:35 INFO [INSERTED] Inserted 2000 Products to Category ID 20890
15-05-2023 19:16:30 INFO [INSERTED] Inserted 1643 Products to Category ID 24986
15-05-2023 19:16:31 INFO [INSERTED] Inserted 0001 Products to Category ID 20912
15-05-2023 19:16:47 INFO [INSERTED] Inserted 0044 Products to Category ID 20914
15-05-2023 19:17:35 INFO [INSERTED] Inserted 0070 Products to Category ID 20924
15-05-2023 19:17:37 INFO [INSERTED] Inserted 0005 Products to Category ID 20918
15-05-2023 19:19:05 INFO [INSERTED] Inserted 0209 Products to Category ID 20920
15-05-2023 19:20:55 INFO [INSERTED] Inserted 0204 Products to Category ID 20922
15-05-2023 19:21:34 INFO [INSERTED] Inserted 0047 Products to Category ID 20932
15-05-2023 19:21:34 INFO [INSERTED] Inserted 0001 Products to Category ID 20936
15-05-2023 19:21:42 INFO [INSERTED] Inserted 0022 Products to Category ID 20938
15-05-2023 19:22:03 INFO [INSERTED] Inserted 0053 Products to Category ID 20940
15-05-2023 19:22:30 INFO [INSERTED] Inserted 0041 Products to Category ID 20948
15-05-2023 19:22:55 INFO [INSERTED] Inserted 0066 Products to Category ID 20950
15-05-2023 19:23:08 INFO [INSERTED] Inserted 0029 Products to Category ID 20952
15-05-2023 19:23:28 INFO [INSERTED] Inserted 0028 Products to Category ID 20964
15-05-2023 19:23:58 INFO [INSERTED] Inserted 0080 Products to Category ID 20966
15-05-2023 19:25:01 INFO [INSERTED] Inserted 0111 Products to Category ID 20968
15-05-2023 19:25:05 INFO [INSERTED] Inserted 0010 Products to Category ID 20970
15-05-2023 19:25:11 INFO [INSERTED] Inserted 0017 Products to Category ID 20972
15-05-2023 19:25:27 INFO [INSERTED] Inserted 0014 Products to Category ID 20974
15-05-2023 19:25:30 INFO [INSERTED] Inserted 0007 Products to Category ID 20976
15-05-2023 19:25:33 INFO [INSERTED] Inserted 0009 Products to Category ID 20978
15-05-2023 19:27:03 ERROR Traceback (most recent call last):
  File "/home/ngkhachuy/anaconda3/lib/python3.9/site-packages/urllib3/response.py", line 761, in _update_chunk_length
    self.chunk_left = int(line, 16)
ValueError: invalid literal for int() with base 16: b''

During handling of the above exception, another exception occurred:

Traceback (most recent call last):
  File "/home/ngkhachuy/anaconda3/lib/python3.9/site-packages/urllib3/response.py", line 444, in _error_catcher
    yield
  File "/home/ngkhachuy/anaconda3/lib/python3.9/site-packages/urllib3/response.py", line 828, in read_chunked
    self._update_chunk_length()
  File "/home/ngkhachuy/anaconda3/lib/python3.9/site-packages/urllib3/response.py", line 765, in _update_chunk_length
    raise InvalidChunkLength(self, line)
urllib3.exceptions.InvalidChunkLength: InvalidChunkLength(got length b'', 0 bytes read)

During handling of the above exception, another exception occurred:

Traceback (most recent call last):
  File "/home/ngkhachuy/anaconda3/lib/python3.9/site-packages/requests/models.py", line 816, in generate
    yield from self.raw.stream(chunk_size, decode_content=True)
  File "/home/ngkhachuy/anaconda3/lib/python3.9/site-packages/urllib3/response.py", line 624, in stream
    for line in self.read_chunked(amt, decode_content=decode_content):
  File "/home/ngkhachuy/anaconda3/lib/python3.9/site-packages/urllib3/response.py", line 857, in read_chunked
    self._original_response.close()
  File "/home/ngkhachuy/anaconda3/lib/python3.9/contextlib.py", line 137, in __exit__
    self.gen.throw(typ, value, traceback)
  File "/home/ngkhachuy/anaconda3/lib/python3.9/site-packages/urllib3/response.py", line 461, in _error_catcher
    raise ProtocolError("Connection broken: %r" % e, e)
urllib3.exceptions.ProtocolError: ("Connection broken: InvalidChunkLength(got length b'', 0 bytes read)", InvalidChunkLength(got length b'', 0 bytes read))

During handling of the above exception, another exception occurred:

Traceback (most recent call last):
  File "/home/ngkhachuy/PROJECT/DEC_PJ4_TIKI.VN/get_product_API.py", line 95, in <module>
    prod_detail = COMMON.send_get_request(PRODUCT_DETAIL_API % p_id)
  File "/home/ngkhachuy/PROJECT/DEC_PJ4_TIKI.VN/COMMON.py", line 24, in send_get_request
    res_tmp = requests.get(url, headers={"user-agent":
  File "/home/ngkhachuy/anaconda3/lib/python3.9/site-packages/requests/api.py", line 73, in get
    return request("get", url, params=params, **kwargs)
  File "/home/ngkhachuy/anaconda3/lib/python3.9/site-packages/requests/api.py", line 59, in request
    return session.request(method=method, url=url, **kwargs)
  File "/home/ngkhachuy/anaconda3/lib/python3.9/site-packages/requests/sessions.py", line 587, in request
    resp = self.send(prep, **send_kwargs)
  File "/home/ngkhachuy/anaconda3/lib/python3.9/site-packages/requests/sessions.py", line 745, in send
    r.content
  File "/home/ngkhachuy/anaconda3/lib/python3.9/site-packages/requests/models.py", line 899, in content
    self._content = b"".join(self.iter_content(CONTENT_CHUNK_SIZE)) or b""
  File "/home/ngkhachuy/anaconda3/lib/python3.9/site-packages/requests/models.py", line 818, in generate
    raise ChunkedEncodingError(e)
requests.exceptions.ChunkedEncodingError: ("Connection broken: InvalidChunkLength(got length b'', 0 bytes read)", InvalidChunkLength(got length b'', 0 bytes read))

15-05-2023 19:27:03 ERROR ERROR AT CATEGORY: 24988
15-05-2023 19:27:03 ERROR ERROR AT PRODUCT: 247311763
15-05-2023 19:27:03 ERROR [ERROR] Restart script!
15-05-2023 19:27:03 INFO STARTED TIME: 19:27:03 15/05/2023
15-05-2023 19:28:55 INFO [INSERTED] Inserted 0222 Products to Category ID 24988
15-05-2023 19:29:34 INFO [INSERTED] Inserted 0076 Products to Category ID 20982
15-05-2023 19:29:46 INFO [INSERTED] Inserted 0032 Products to Category ID 20984
15-05-2023 19:30:05 INFO [INSERTED] Inserted 0046 Products to Category ID 20986
15-05-2023 19:30:33 INFO [INSERTED] Inserted 0045 Products to Category ID 24992
15-05-2023 19:30:39 INFO [INSERTED] Inserted 0013 Products to Category ID 24994
15-05-2023 19:32:01 INFO [INSERTED] Inserted 0167 Products to Category ID 20992
15-05-2023 19:35:10 INFO [INSERTED] Inserted 0359 Products to Category ID 21002
15-05-2023 19:42:30 INFO [INSERTED] Inserted 0870 Products to Category ID 21004
15-05-2023 19:48:47 INFO [INSERTED] Inserted 0743 Products to Category ID 21006
15-05-2023 19:52:48 INFO [INSERTED] Inserted 0479 Products to Category ID 21008
15-05-2023 20:09:57 INFO [INSERTED] Inserted 2000 Products to Category ID 21012
15-05-2023 20:23:31 ERROR Traceback (most recent call last):
  File "/home/ngkhachuy/anaconda3/lib/python3.9/site-packages/urllib3/connectionpool.py", line 703, in urlopen
    httplib_response = self._make_request(
  File "/home/ngkhachuy/anaconda3/lib/python3.9/site-packages/urllib3/connectionpool.py", line 386, in _make_request
    self._validate_conn(conn)
  File "/home/ngkhachuy/anaconda3/lib/python3.9/site-packages/urllib3/connectionpool.py", line 1042, in _validate_conn
    conn.connect()
  File "/home/ngkhachuy/anaconda3/lib/python3.9/site-packages/urllib3/connection.py", line 414, in connect
    self.sock = ssl_wrap_socket(
  File "/home/ngkhachuy/anaconda3/lib/python3.9/site-packages/urllib3/util/ssl_.py", line 449, in ssl_wrap_socket
    ssl_sock = _ssl_wrap_socket_impl(
  File "/home/ngkhachuy/anaconda3/lib/python3.9/site-packages/urllib3/util/ssl_.py", line 493, in _ssl_wrap_socket_impl
    return ssl_context.wrap_socket(sock, server_hostname=server_hostname)
  File "/home/ngkhachuy/anaconda3/lib/python3.9/ssl.py", line 501, in wrap_socket
    return self.sslsocket_class._create(
  File "/home/ngkhachuy/anaconda3/lib/python3.9/ssl.py", line 1041, in _create
    self.do_handshake()
  File "/home/ngkhachuy/anaconda3/lib/python3.9/ssl.py", line 1310, in do_handshake
    self._sslobj.do_handshake()
ssl.SSLEOFError: EOF occurred in violation of protocol (_ssl.c:1129)

During handling of the above exception, another exception occurred:

Traceback (most recent call last):
  File "/home/ngkhachuy/anaconda3/lib/python3.9/site-packages/requests/adapters.py", line 489, in send
    resp = conn.urlopen(
  File "/home/ngkhachuy/anaconda3/lib/python3.9/site-packages/urllib3/connectionpool.py", line 787, in urlopen
    retries = retries.increment(
  File "/home/ngkhachuy/anaconda3/lib/python3.9/site-packages/urllib3/util/retry.py", line 592, in increment
    raise MaxRetryError(_pool, url, error or ResponseError(cause))
urllib3.exceptions.MaxRetryError: HTTPSConnectionPool(host='tiki.vn', port=443): Max retries exceeded with url: /api/v2/products/94361517 (Caused by SSLError(SSLEOFError(8, 'EOF occurred in violation of protocol (_ssl.c:1129)')))

During handling of the above exception, another exception occurred:

Traceback (most recent call last):
  File "/home/ngkhachuy/PROJECT/DEC_PJ4_TIKI.VN/get_product_API.py", line 95, in <module>
    prod_detail = COMMON.send_get_request(PRODUCT_DETAIL_API % p_id)
  File "/home/ngkhachuy/PROJECT/DEC_PJ4_TIKI.VN/COMMON.py", line 24, in send_get_request
    res_tmp = requests.get(url, headers={"user-agent":
  File "/home/ngkhachuy/anaconda3/lib/python3.9/site-packages/requests/api.py", line 73, in get
    return request("get", url, params=params, **kwargs)
  File "/home/ngkhachuy/anaconda3/lib/python3.9/site-packages/requests/api.py", line 59, in request
    return session.request(method=method, url=url, **kwargs)
  File "/home/ngkhachuy/anaconda3/lib/python3.9/site-packages/requests/sessions.py", line 587, in request
    resp = self.send(prep, **send_kwargs)
  File "/home/ngkhachuy/anaconda3/lib/python3.9/site-packages/requests/sessions.py", line 701, in send
    r = adapter.send(request, **kwargs)
  File "/home/ngkhachuy/anaconda3/lib/python3.9/site-packages/requests/adapters.py", line 563, in send
    raise SSLError(e, request=request)
requests.exceptions.SSLError: HTTPSConnectionPool(host='tiki.vn', port=443): Max retries exceeded with url: /api/v2/products/94361517 (Caused by SSLError(SSLEOFError(8, 'EOF occurred in violation of protocol (_ssl.c:1129)')))

15-05-2023 20:23:31 ERROR ERROR AT CATEGORY: 21016
15-05-2023 20:23:31 ERROR ERROR AT PRODUCT: 94361517
15-05-2023 20:23:31 ERROR [ERROR] Restart script!
15-05-2023 20:23:33 INFO STARTED TIME: 20:23:33 15/05/2023
15-05-2023 20:40:14 INFO [INSERTED] Inserted 2000 Products to Category ID 21016
15-05-2023 20:43:48 INFO [INSERTED] Inserted 0420 Products to Category ID 21018
15-05-2023 20:56:27 ERROR Traceback (most recent call last):
  File "/home/ngkhachuy/anaconda3/lib/python3.9/site-packages/urllib3/response.py", line 444, in _error_catcher
    yield
  File "/home/ngkhachuy/anaconda3/lib/python3.9/site-packages/urllib3/response.py", line 828, in read_chunked
    self._update_chunk_length()
  File "/home/ngkhachuy/anaconda3/lib/python3.9/site-packages/urllib3/response.py", line 758, in _update_chunk_length
    line = self._fp.fp.readline()
  File "/home/ngkhachuy/anaconda3/lib/python3.9/socket.py", line 704, in readinto
    return self._sock.recv_into(b)
  File "/home/ngkhachuy/anaconda3/lib/python3.9/ssl.py", line 1242, in recv_into
    return self.read(nbytes, buffer)
  File "/home/ngkhachuy/anaconda3/lib/python3.9/ssl.py", line 1100, in read
    return self._sslobj.read(len, buffer)
socket.timeout: The read operation timed out

During handling of the above exception, another exception occurred:

Traceback (most recent call last):
  File "/home/ngkhachuy/anaconda3/lib/python3.9/site-packages/requests/models.py", line 816, in generate
    yield from self.raw.stream(chunk_size, decode_content=True)
  File "/home/ngkhachuy/anaconda3/lib/python3.9/site-packages/urllib3/response.py", line 624, in stream
    for line in self.read_chunked(amt, decode_content=decode_content):
  File "/home/ngkhachuy/anaconda3/lib/python3.9/site-packages/urllib3/response.py", line 857, in read_chunked
    self._original_response.close()
  File "/home/ngkhachuy/anaconda3/lib/python3.9/contextlib.py", line 137, in __exit__
    self.gen.throw(typ, value, traceback)
  File "/home/ngkhachuy/anaconda3/lib/python3.9/site-packages/urllib3/response.py", line 449, in _error_catcher
    raise ReadTimeoutError(self._pool, None, "Read timed out.")
urllib3.exceptions.ReadTimeoutError: HTTPSConnectionPool(host='tiki.vn', port=443): Read timed out.

During handling of the above exception, another exception occurred:

Traceback (most recent call last):
  File "/home/ngkhachuy/PROJECT/DEC_PJ4_TIKI.VN/get_product_API.py", line 95, in <module>
    prod_detail = COMMON.send_get_request(PRODUCT_DETAIL_API % p_id)
  File "/home/ngkhachuy/PROJECT/DEC_PJ4_TIKI.VN/COMMON.py", line 24, in send_get_request
    res_tmp = requests.get(url, headers={"user-agent":
  File "/home/ngkhachuy/anaconda3/lib/python3.9/site-packages/requests/api.py", line 73, in get
    return request("get", url, params=params, **kwargs)
  File "/home/ngkhachuy/anaconda3/lib/python3.9/site-packages/requests/api.py", line 59, in request
    return session.request(method=method, url=url, **kwargs)
  File "/home/ngkhachuy/anaconda3/lib/python3.9/site-packages/requests/sessions.py", line 587, in request
    resp = self.send(prep, **send_kwargs)
  File "/home/ngkhachuy/anaconda3/lib/python3.9/site-packages/requests/sessions.py", line 745, in send
    r.content
  File "/home/ngkhachuy/anaconda3/lib/python3.9/site-packages/requests/models.py", line 899, in content
    self._content = b"".join(self.iter_content(CONTENT_CHUNK_SIZE)) or b""
  File "/home/ngkhachuy/anaconda3/lib/python3.9/site-packages/requests/models.py", line 822, in generate
    raise ConnectionError(e)
requests.exceptions.ConnectionError: HTTPSConnectionPool(host='tiki.vn', port=443): Read timed out.

15-05-2023 20:56:27 ERROR ERROR AT CATEGORY: 21020
15-05-2023 20:56:27 ERROR ERROR AT PRODUCT: 207879162
15-05-2023 20:56:27 ERROR [ERROR] Restart script!
15-05-2023 20:56:28 INFO STARTED TIME: 20:56:28 15/05/2023
15-05-2023 21:12:46 INFO [INSERTED] Inserted 1894 Products to Category ID 21020
15-05-2023 21:12:51 INFO [INSERTED] Inserted 0011 Products to Category ID 21024
15-05-2023 21:13:10 INFO [INSERTED] Inserted 0031 Products to Category ID 21026
15-05-2023 21:18:56 INFO [INSERTED] Inserted 0660 Products to Category ID 21028
15-05-2023 21:18:59 INFO [INSERTED] Inserted 0007 Products to Category ID 21030
15-05-2023 21:19:42 INFO [INSERTED] Inserted 0054 Products to Category ID 21034
15-05-2023 21:27:58 ERROR Traceback (most recent call last):
  File "/home/ngkhachuy/anaconda3/lib/python3.9/site-packages/urllib3/response.py", line 761, in _update_chunk_length
    self.chunk_left = int(line, 16)
ValueError: invalid literal for int() with base 16: b''

During handling of the above exception, another exception occurred:

Traceback (most recent call last):
  File "/home/ngkhachuy/anaconda3/lib/python3.9/site-packages/urllib3/response.py", line 444, in _error_catcher
    yield
  File "/home/ngkhachuy/anaconda3/lib/python3.9/site-packages/urllib3/response.py", line 828, in read_chunked
    self._update_chunk_length()
  File "/home/ngkhachuy/anaconda3/lib/python3.9/site-packages/urllib3/response.py", line 765, in _update_chunk_length
    raise InvalidChunkLength(self, line)
urllib3.exceptions.InvalidChunkLength: InvalidChunkLength(got length b'', 0 bytes read)

During handling of the above exception, another exception occurred:

Traceback (most recent call last):
  File "/home/ngkhachuy/anaconda3/lib/python3.9/site-packages/requests/models.py", line 816, in generate
    yield from self.raw.stream(chunk_size, decode_content=True)
  File "/home/ngkhachuy/anaconda3/lib/python3.9/site-packages/urllib3/response.py", line 624, in stream
    for line in self.read_chunked(amt, decode_content=decode_content):
  File "/home/ngkhachuy/anaconda3/lib/python3.9/site-packages/urllib3/response.py", line 857, in read_chunked
    self._original_response.close()
  File "/home/ngkhachuy/anaconda3/lib/python3.9/contextlib.py", line 137, in __exit__
    self.gen.throw(typ, value, traceback)
  File "/home/ngkhachuy/anaconda3/lib/python3.9/site-packages/urllib3/response.py", line 461, in _error_catcher
    raise ProtocolError("Connection broken: %r" % e, e)
urllib3.exceptions.ProtocolError: ("Connection broken: InvalidChunkLength(got length b'', 0 bytes read)", InvalidChunkLength(got length b'', 0 bytes read))

During handling of the above exception, another exception occurred:

Traceback (most recent call last):
  File "/home/ngkhachuy/PROJECT/DEC_PJ4_TIKI.VN/get_product_API.py", line 95, in <module>
    prod_detail = COMMON.send_get_request(PRODUCT_DETAIL_API % p_id)
  File "/home/ngkhachuy/PROJECT/DEC_PJ4_TIKI.VN/COMMON.py", line 24, in send_get_request
    res_tmp = requests.get(url, headers={"user-agent":
  File "/home/ngkhachuy/anaconda3/lib/python3.9/site-packages/requests/api.py", line 73, in get
    return request("get", url, params=params, **kwargs)
  File "/home/ngkhachuy/anaconda3/lib/python3.9/site-packages/requests/api.py", line 59, in request
    return session.request(method=method, url=url, **kwargs)
  File "/home/ngkhachuy/anaconda3/lib/python3.9/site-packages/requests/sessions.py", line 587, in request
    resp = self.send(prep, **send_kwargs)
  File "/home/ngkhachuy/anaconda3/lib/python3.9/site-packages/requests/sessions.py", line 745, in send
    r.content
  File "/home/ngkhachuy/anaconda3/lib/python3.9/site-packages/requests/models.py", line 899, in content
    self._content = b"".join(self.iter_content(CONTENT_CHUNK_SIZE)) or b""
  File "/home/ngkhachuy/anaconda3/lib/python3.9/site-packages/requests/models.py", line 818, in generate
    raise ChunkedEncodingError(e)
requests.exceptions.ChunkedEncodingError: ("Connection broken: InvalidChunkLength(got length b'', 0 bytes read)", InvalidChunkLength(got length b'', 0 bytes read))

15-05-2023 21:27:58 ERROR ERROR AT CATEGORY: 21036
15-05-2023 21:27:58 ERROR ERROR AT PRODUCT: 208594203
15-05-2023 21:27:58 ERROR [ERROR] Restart script!
15-05-2023 21:27:59 INFO STARTED TIME: 21:27:59 15/05/2023
15-05-2023 21:44:50 INFO [INSERTED] Inserted 2000 Products to Category ID 21036
15-05-2023 21:44:58 INFO [INSERTED] Inserted 0016 Products to Category ID 21038
15-05-2023 21:45:36 INFO [INSERTED] Inserted 0066 Products to Category ID 21040
15-05-2023 21:45:57 INFO [INSERTED] Inserted 0048 Products to Category ID 21042
15-05-2023 21:46:10 INFO [INSERTED] Inserted 0034 Products to Category ID 21044
15-05-2023 21:46:34 INFO [INSERTED] Inserted 0004 Products to Category ID 21056
15-05-2023 21:46:40 INFO [INSERTED] Inserted 0015 Products to Category ID 21058
15-05-2023 21:52:47 INFO [INSERTED] Inserted 0739 Products to Category ID 21060
15-05-2023 21:53:03 INFO [INSERTED] Inserted 0020 Products to Category ID 21076
15-05-2023 22:09:53 INFO [INSERTED] Inserted 2000 Products to Category ID 21084
15-05-2023 22:10:31 INFO [INSERTED] Inserted 0044 Products to Category ID 21086
15-05-2023 22:17:58 INFO [INSERTED] Inserted 0897 Products to Category ID 21088
15-05-2023 22:17:59 INFO [INSERTED] Inserted 0004 Products to Category ID 21092
15-05-2023 22:34:47 INFO [INSERTED] Inserted 2000 Products to Category ID 21094
15-05-2023 22:51:40 INFO [INSERTED] Inserted 2000 Products to Category ID 21106
15-05-2023 22:57:28 INFO [INSERTED] Inserted 0677 Products to Category ID 21114
15-05-2023 23:02:06 INFO [INSERTED] Inserted 0567 Products to Category ID 21120
15-05-2023 23:07:07 INFO [INSERTED] Inserted 0608 Products to Category ID 21132
15-05-2023 23:07:32 INFO [INSERTED] Inserted 0008 Products to Category ID 21170
15-05-2023 23:07:42 INFO [INSERTED] Inserted 0029 Products to Category ID 21172
15-05-2023 23:07:43 INFO [INSERTED] Inserted 0002 Products to Category ID 21174
15-05-2023 23:14:11 ERROR [TIMEOUT] Restart script!
15-05-2023 23:14:11 INFO STARTED TIME: 23:14:11 15/05/2023
15-05-2023 23:21:33 INFO [INSERTED] Inserted 0857 Products to Category ID 21176
15-05-2023 23:21:36 INFO [INSERTED] Inserted 0007 Products to Category ID 21234
15-05-2023 23:32:33 INFO [INSERTED] Inserted 1307 Products to Category ID 21236
15-05-2023 23:49:35 INFO [INSERTED] Inserted 2000 Products to Category ID 21238
16-05-2023 00:06:32 INFO [INSERTED] Inserted 2000 Products to Category ID 21242
16-05-2023 00:09:44 INFO [INSERTED] Inserted 0393 Products to Category ID 21244
16-05-2023 00:10:50 INFO [INSERTED] Inserted 0105 Products to Category ID 24984
16-05-2023 00:15:56 INFO [INSERTED] Inserted 0621 Products to Category ID 21246
16-05-2023 00:15:58 INFO [INSERTED] Inserted 0003 Products to Category ID 21248
16-05-2023 00:32:57 INFO [INSERTED] Inserted 2000 Products to Category ID 21252
16-05-2023 00:33:30 INFO [INSERTED] Inserted 0060 Products to Category ID 21254
16-05-2023 00:33:54 ERROR [TIMEOUT] Restart script!
16-05-2023 00:33:54 INFO STARTED TIME: 00:33:54 16/05/2023
16-05-2023 00:51:48 INFO [INSERTED] Inserted 2000 Products to Category ID 21260
16-05-2023 01:07:47 ERROR [TIMEOUT] Restart script!
16-05-2023 01:07:47 INFO STARTED TIME: 01:07:47 16/05/2023
16-05-2023 01:24:38 INFO [INSERTED] Inserted 2000 Products to Category ID 21270
16-05-2023 01:41:33 INFO [INSERTED] Inserted 2000 Products to Category ID 21272
16-05-2023 01:58:38 INFO [INSERTED] Inserted 2000 Products to Category ID 21274
16-05-2023 02:15:39 INFO [INSERTED] Inserted 2000 Products to Category ID 21276
16-05-2023 02:32:29 INFO [INSERTED] Inserted 2000 Products to Category ID 21280
16-05-2023 02:36:05 ERROR [TIMEOUT] Restart script!
16-05-2023 02:36:06 INFO STARTED TIME: 02:36:06 16/05/2023
16-05-2023 02:53:12 INFO [INSERTED] Inserted 2000 Products to Category ID 21282
16-05-2023 03:10:07 INFO [INSERTED] Inserted 2000 Products to Category ID 21284
16-05-2023 03:26:54 ERROR [TIMEOUT] Restart script!
16-05-2023 03:26:54 INFO STARTED TIME: 03:26:54 16/05/2023
16-05-2023 03:27:01 ERROR [TIMEOUT] Restart script!
16-05-2023 03:27:01 INFO STARTED TIME: 03:27:01 16/05/2023
16-05-2023 03:27:08 ERROR [TIMEOUT] Restart script!
16-05-2023 03:27:08 INFO STARTED TIME: 03:27:08 16/05/2023
16-05-2023 03:27:18 ERROR [TIMEOUT] Restart script!
16-05-2023 03:27:18 INFO STARTED TIME: 03:27:18 16/05/2023
16-05-2023 03:32:46 ERROR [TIMEOUT] Restart script!
16-05-2023 03:32:47 INFO STARTED TIME: 03:32:47 16/05/2023
16-05-2023 03:33:06 ERROR [TIMEOUT] Restart script!
16-05-2023 03:33:06 INFO STARTED TIME: 03:33:06 16/05/2023
16-05-2023 03:33:13 ERROR [TIMEOUT] Restart script!
16-05-2023 03:33:14 INFO STARTED TIME: 03:33:14 16/05/2023
16-05-2023 03:34:13 ERROR [TIMEOUT] Restart script!
16-05-2023 03:34:14 INFO STARTED TIME: 03:34:14 16/05/2023
16-05-2023 03:51:01 INFO [INSERTED] Inserted 2000 Products to Category ID 21286
16-05-2023 04:08:03 INFO [INSERTED] Inserted 2000 Products to Category ID 21288
16-05-2023 04:14:36 INFO [INSERTED] Inserted 0790 Products to Category ID 24996
16-05-2023 04:18:59 ERROR [TIMEOUT] Restart script!
16-05-2023 04:18:59 INFO STARTED TIME: 04:18:59 16/05/2023
16-05-2023 04:35:47 INFO [INSERTED] Inserted 2000 Products to Category ID 24998
16-05-2023 04:52:40 INFO [INSERTED] Inserted 2000 Products to Category ID 25000
16-05-2023 04:53:07 INFO [INSERTED] Inserted 0072 Products to Category ID 21302
16-05-2023 05:09:55 INFO [INSERTED] Inserted 2000 Products to Category ID 21304
16-05-2023 05:22:47 INFO [INSERTED] Inserted 1528 Products to Category ID 21306
16-05-2023 05:39:39 INFO [INSERTED] Inserted 2000 Products to Category ID 21308
16-05-2023 05:49:36 INFO [INSERTED] Inserted 1151 Products to Category ID 21310
16-05-2023 05:49:55 INFO [INSERTED] Inserted 0047 Products to Category ID 21312
16-05-2023 05:55:01 INFO [INSERTED] Inserted 0626 Products to Category ID 21314
16-05-2023 06:11:47 INFO [INSERTED] Inserted 2000 Products to Category ID 21316
16-05-2023 06:11:48 INFO [INSERTED] Inserted 0003 Products to Category ID 21318
16-05-2023 06:12:00 INFO [INSERTED] Inserted 0033 Products to Category ID 21320
16-05-2023 06:12:31 INFO [INSERTED] Inserted 0023 Products to Category ID 21322
16-05-2023 06:13:50 INFO [INSERTED] Inserted 0154 Products to Category ID 21326
16-05-2023 06:14:30 INFO [INSERTED] Inserted 0085 Products to Category ID 21328
16-05-2023 06:20:01 INFO [INSERTED] Inserted 0663 Products to Category ID 21330
16-05-2023 06:20:52 INFO [INSERTED] Inserted 0112 Products to Category ID 21332
16-05-2023 06:21:00 INFO [INSERTED] Inserted 0020 Products to Category ID 25002
16-05-2023 06:24:05 INFO [INSERTED] Inserted 0350 Products to Category ID 25004
16-05-2023 06:24:27 INFO [INSERTED] Inserted 0030 Products to Category ID 25006
16-05-2023 06:25:02 INFO [INSERTED] Inserted 0097 Products to Category ID 25040
16-05-2023 06:25:41 INFO [INSERTED] Inserted 0048 Products to Category ID 25042
16-05-2023 06:26:04 INFO [INSERTED] Inserted 0066 Products to Category ID 25046
16-05-2023 06:26:05 INFO [INSERTED] Inserted 0001 Products to Category ID 25048
16-05-2023 06:27:51 INFO [INSERTED] Inserted 0204 Products to Category ID 25050
16-05-2023 06:29:41 INFO [INSERTED] Inserted 0213 Products to Category ID 25052
16-05-2023 06:39:26 INFO [INSERTED] Inserted 1154 Products to Category ID 21336
16-05-2023 06:41:38 INFO [INSERTED] Inserted 0251 Products to Category ID 21338
16-05-2023 06:42:12 INFO [INSERTED] Inserted 0092 Products to Category ID 21340
16-05-2023 06:59:08 INFO [INSERTED] Inserted 2000 Products to Category ID 21342
16-05-2023 07:08:57 ERROR Traceback (most recent call last):
  File "/home/ngkhachuy/anaconda3/lib/python3.9/site-packages/urllib3/connectionpool.py", line 703, in urlopen
    httplib_response = self._make_request(
  File "/home/ngkhachuy/anaconda3/lib/python3.9/site-packages/urllib3/connectionpool.py", line 386, in _make_request
    self._validate_conn(conn)
  File "/home/ngkhachuy/anaconda3/lib/python3.9/site-packages/urllib3/connectionpool.py", line 1042, in _validate_conn
    conn.connect()
  File "/home/ngkhachuy/anaconda3/lib/python3.9/site-packages/urllib3/connection.py", line 414, in connect
    self.sock = ssl_wrap_socket(
  File "/home/ngkhachuy/anaconda3/lib/python3.9/site-packages/urllib3/util/ssl_.py", line 449, in ssl_wrap_socket
    ssl_sock = _ssl_wrap_socket_impl(
  File "/home/ngkhachuy/anaconda3/lib/python3.9/site-packages/urllib3/util/ssl_.py", line 493, in _ssl_wrap_socket_impl
    return ssl_context.wrap_socket(sock, server_hostname=server_hostname)
  File "/home/ngkhachuy/anaconda3/lib/python3.9/ssl.py", line 501, in wrap_socket
    return self.sslsocket_class._create(
  File "/home/ngkhachuy/anaconda3/lib/python3.9/ssl.py", line 1041, in _create
    self.do_handshake()
  File "/home/ngkhachuy/anaconda3/lib/python3.9/ssl.py", line 1310, in do_handshake
    self._sslobj.do_handshake()
ssl.SSLEOFError: EOF occurred in violation of protocol (_ssl.c:1129)

During handling of the above exception, another exception occurred:

Traceback (most recent call last):
  File "/home/ngkhachuy/anaconda3/lib/python3.9/site-packages/requests/adapters.py", line 489, in send
    resp = conn.urlopen(
  File "/home/ngkhachuy/anaconda3/lib/python3.9/site-packages/urllib3/connectionpool.py", line 787, in urlopen
    retries = retries.increment(
  File "/home/ngkhachuy/anaconda3/lib/python3.9/site-packages/urllib3/util/retry.py", line 592, in increment
    raise MaxRetryError(_pool, url, error or ResponseError(cause))
urllib3.exceptions.MaxRetryError: HTTPSConnectionPool(host='tiki.vn', port=443): Max retries exceeded with url: /api/v2/products/165181477 (Caused by SSLError(SSLEOFError(8, 'EOF occurred in violation of protocol (_ssl.c:1129)')))

During handling of the above exception, another exception occurred:

Traceback (most recent call last):
  File "/home/ngkhachuy/PROJECT/DEC_PJ4_TIKI.VN/get_product_API.py", line 95, in <module>
    prod_detail = COMMON.send_get_request(PRODUCT_DETAIL_API % p_id)
  File "/home/ngkhachuy/PROJECT/DEC_PJ4_TIKI.VN/COMMON.py", line 24, in send_get_request
    res_tmp = requests.get(url, headers={"user-agent":
  File "/home/ngkhachuy/anaconda3/lib/python3.9/site-packages/requests/api.py", line 73, in get
    return request("get", url, params=params, **kwargs)
  File "/home/ngkhachuy/anaconda3/lib/python3.9/site-packages/requests/api.py", line 59, in request
    return session.request(method=method, url=url, **kwargs)
  File "/home/ngkhachuy/anaconda3/lib/python3.9/site-packages/requests/sessions.py", line 587, in request
    resp = self.send(prep, **send_kwargs)
  File "/home/ngkhachuy/anaconda3/lib/python3.9/site-packages/requests/sessions.py", line 701, in send
    r = adapter.send(request, **kwargs)
  File "/home/ngkhachuy/anaconda3/lib/python3.9/site-packages/requests/adapters.py", line 563, in send
    raise SSLError(e, request=request)
requests.exceptions.SSLError: HTTPSConnectionPool(host='tiki.vn', port=443): Max retries exceeded with url: /api/v2/products/165181477 (Caused by SSLError(SSLEOFError(8, 'EOF occurred in violation of protocol (_ssl.c:1129)')))

16-05-2023 07:08:57 ERROR ERROR AT CATEGORY: 21344
16-05-2023 07:08:57 ERROR ERROR AT PRODUCT: 165181477
16-05-2023 07:08:57 ERROR [ERROR] Restart script!
16-05-2023 07:08:58 INFO STARTED TIME: 07:08:58 16/05/2023
16-05-2023 07:22:37 ERROR Traceback (most recent call last):
  File "/home/ngkhachuy/anaconda3/lib/python3.9/site-packages/urllib3/connectionpool.py", line 703, in urlopen
    httplib_response = self._make_request(
  File "/home/ngkhachuy/anaconda3/lib/python3.9/site-packages/urllib3/connectionpool.py", line 386, in _make_request
    self._validate_conn(conn)
  File "/home/ngkhachuy/anaconda3/lib/python3.9/site-packages/urllib3/connectionpool.py", line 1042, in _validate_conn
    conn.connect()
  File "/home/ngkhachuy/anaconda3/lib/python3.9/site-packages/urllib3/connection.py", line 414, in connect
    self.sock = ssl_wrap_socket(
  File "/home/ngkhachuy/anaconda3/lib/python3.9/site-packages/urllib3/util/ssl_.py", line 449, in ssl_wrap_socket
    ssl_sock = _ssl_wrap_socket_impl(
  File "/home/ngkhachuy/anaconda3/lib/python3.9/site-packages/urllib3/util/ssl_.py", line 493, in _ssl_wrap_socket_impl
    return ssl_context.wrap_socket(sock, server_hostname=server_hostname)
  File "/home/ngkhachuy/anaconda3/lib/python3.9/ssl.py", line 501, in wrap_socket
    return self.sslsocket_class._create(
  File "/home/ngkhachuy/anaconda3/lib/python3.9/ssl.py", line 1041, in _create
    self.do_handshake()
  File "/home/ngkhachuy/anaconda3/lib/python3.9/ssl.py", line 1310, in do_handshake
    self._sslobj.do_handshake()
ssl.SSLEOFError: EOF occurred in violation of protocol (_ssl.c:1129)

During handling of the above exception, another exception occurred:

Traceback (most recent call last):
  File "/home/ngkhachuy/anaconda3/lib/python3.9/site-packages/requests/adapters.py", line 489, in send
    resp = conn.urlopen(
  File "/home/ngkhachuy/anaconda3/lib/python3.9/site-packages/urllib3/connectionpool.py", line 787, in urlopen
    retries = retries.increment(
  File "/home/ngkhachuy/anaconda3/lib/python3.9/site-packages/urllib3/util/retry.py", line 592, in increment
    raise MaxRetryError(_pool, url, error or ResponseError(cause))
urllib3.exceptions.MaxRetryError: HTTPSConnectionPool(host='tiki.vn', port=443): Max retries exceeded with url: /api/v2/products/178757810 (Caused by SSLError(SSLEOFError(8, 'EOF occurred in violation of protocol (_ssl.c:1129)')))

During handling of the above exception, another exception occurred:

Traceback (most recent call last):
  File "/home/ngkhachuy/PROJECT/DEC_PJ4_TIKI.VN/get_product_API.py", line 95, in <module>
    prod_detail = COMMON.send_get_request(PRODUCT_DETAIL_API % p_id)
  File "/home/ngkhachuy/PROJECT/DEC_PJ4_TIKI.VN/COMMON.py", line 24, in send_get_request
    res_tmp = requests.get(url, headers={"user-agent":
  File "/home/ngkhachuy/anaconda3/lib/python3.9/site-packages/requests/api.py", line 73, in get
    return request("get", url, params=params, **kwargs)
  File "/home/ngkhachuy/anaconda3/lib/python3.9/site-packages/requests/api.py", line 59, in request
    return session.request(method=method, url=url, **kwargs)
  File "/home/ngkhachuy/anaconda3/lib/python3.9/site-packages/requests/sessions.py", line 587, in request
    resp = self.send(prep, **send_kwargs)
  File "/home/ngkhachuy/anaconda3/lib/python3.9/site-packages/requests/sessions.py", line 701, in send
    r = adapter.send(request, **kwargs)
  File "/home/ngkhachuy/anaconda3/lib/python3.9/site-packages/requests/adapters.py", line 563, in send
    raise SSLError(e, request=request)
requests.exceptions.SSLError: HTTPSConnectionPool(host='tiki.vn', port=443): Max retries exceeded with url: /api/v2/products/178757810 (Caused by SSLError(SSLEOFError(8, 'EOF occurred in violation of protocol (_ssl.c:1129)')))

16-05-2023 07:22:38 ERROR ERROR AT CATEGORY: 21344
16-05-2023 07:22:38 ERROR ERROR AT PRODUCT: 178757810
16-05-2023 07:22:38 ERROR [ERROR] Restart script!
16-05-2023 09:11:37 INFO STARTED TIME: 09:11:37 16/05/2023
16-05-2023 09:28:24 INFO [INSERTED] Inserted 2000 Products to Category ID 21344
16-05-2023 09:29:05 INFO [INSERTED] Inserted 0084 Products to Category ID 25008
16-05-2023 09:29:11 INFO STARTED TIME  : 09:11:37 16/05/2023
16-05-2023 09:29:11 INFO FINISHED TIME : 09:29:11 16/05/2023
16-05-2023 09:29:11 INFO EXECUTION TINE: 0:17:34.316254
16-05-2023 09:29:11 INFO NUMBER OF REQUEST HAD BEEN SENT: 2120
16-05-2023 09:31:14 INFO STARTED TIME: 09:31:14 16/05/2023
16-05-2023 09:32:36 INFO STARTED TIME  : 09:31:14 16/05/2023
16-05-2023 09:32:36 INFO FINISHED TIME : 09:32:36 16/05/2023
16-05-2023 09:32:36 INFO EXECUTION TINE: 0:01:22.514040
16-05-2023 09:32:36 INFO NUMBER OF REQUEST HAD BEEN SENT: 3
16-05-2023 09:33:23 INFO STARTED TIME: 09:33:23 16/05/2023
16-05-2023 09:50:10 INFO [INSERTED] Inserted 2000 Products to Category ID 21348
16-05-2023 09:50:19 INFO STARTED TIME  : 09:33:23 16/05/2023
16-05-2023 09:50:19 INFO FINISHED TIME : 09:50:19 16/05/2023
16-05-2023 09:50:19 INFO EXECUTION TINE: 0:16:55.828813
16-05-2023 09:50:19 INFO NUMBER OF REQUEST HAD BEEN SENT: 2043
16-05-2023 09:52:40 INFO STARTED TIME: 09:52:40 16/05/2023
16-05-2023 10:09:24 INFO [INSERTED] Inserted 2000 Products to Category ID 21350
16-05-2023 10:26:12 INFO [INSERTED] Inserted 2000 Products to Category ID 21352
16-05-2023 10:43:00 INFO [INSERTED] Inserted 2000 Products to Category ID 21354
16-05-2023 10:59:56 INFO [INSERTED] Inserted 2000 Products to Category ID 21358
16-05-2023 11:16:48 INFO [INSERTED] Inserted 2000 Products to Category ID 21360
16-05-2023 11:27:30 ERROR [TIMEOUT] Restart script!
16-05-2023 11:27:31 INFO STARTED TIME: 11:27:31 16/05/2023
16-05-2023 11:27:36 ERROR [TIMEOUT] Restart script!
16-05-2023 11:27:37 INFO STARTED TIME: 11:27:37 16/05/2023
16-05-2023 11:44:26 INFO [INSERTED] Inserted 2000 Products to Category ID 21362
16-05-2023 11:54:06 INFO [INSERTED] Inserted 1140 Products to Category ID 21364
16-05-2023 12:10:52 INFO [INSERTED] Inserted 2000 Products to Category ID 21368
16-05-2023 12:27:49 INFO [INSERTED] Inserted 2000 Products to Category ID 21370
16-05-2023 12:44:30 INFO [INSERTED] Inserted 2000 Products to Category ID 21372
16-05-2023 12:44:42 INFO [INSERTED] Inserted 0005 Products to Category ID 21374
16-05-2023 13:01:47 INFO [INSERTED] Inserted 2000 Products to Category ID 21384
16-05-2023 13:14:09 INFO [INSERTED] Inserted 1463 Products to Category ID 21386
16-05-2023 13:26:50 ERROR ("Connection broken: InvalidChunkLength(got length b'', 0 bytes read)", InvalidChunkLength(got length b'', 0 bytes read))
16-05-2023 13:26:50 ERROR Traceback (most recent call last):
  File "/home/ngkhachuy/anaconda3/lib/python3.9/site-packages/urllib3/response.py", line 761, in _update_chunk_length
    self.chunk_left = int(line, 16)
ValueError: invalid literal for int() with base 16: b''

During handling of the above exception, another exception occurred:

Traceback (most recent call last):
  File "/home/ngkhachuy/anaconda3/lib/python3.9/site-packages/urllib3/response.py", line 444, in _error_catcher
    yield
  File "/home/ngkhachuy/anaconda3/lib/python3.9/site-packages/urllib3/response.py", line 828, in read_chunked
    self._update_chunk_length()
  File "/home/ngkhachuy/anaconda3/lib/python3.9/site-packages/urllib3/response.py", line 765, in _update_chunk_length
    raise InvalidChunkLength(self, line)
urllib3.exceptions.InvalidChunkLength: InvalidChunkLength(got length b'', 0 bytes read)

During handling of the above exception, another exception occurred:

Traceback (most recent call last):
  File "/home/ngkhachuy/anaconda3/lib/python3.9/site-packages/requests/models.py", line 816, in generate
    yield from self.raw.stream(chunk_size, decode_content=True)
  File "/home/ngkhachuy/anaconda3/lib/python3.9/site-packages/urllib3/response.py", line 624, in stream
    for line in self.read_chunked(amt, decode_content=decode_content):
  File "/home/ngkhachuy/anaconda3/lib/python3.9/site-packages/urllib3/response.py", line 857, in read_chunked
    self._original_response.close()
  File "/home/ngkhachuy/anaconda3/lib/python3.9/contextlib.py", line 137, in __exit__
    self.gen.throw(typ, value, traceback)
  File "/home/ngkhachuy/anaconda3/lib/python3.9/site-packages/urllib3/response.py", line 461, in _error_catcher
    raise ProtocolError("Connection broken: %r" % e, e)
urllib3.exceptions.ProtocolError: ("Connection broken: InvalidChunkLength(got length b'', 0 bytes read)", InvalidChunkLength(got length b'', 0 bytes read))

During handling of the above exception, another exception occurred:

Traceback (most recent call last):
  File "/home/ngkhachuy/PROJECT/DEC_PJ4_TIKI.VN/get_product_API.py", line 94, in <module>
    prod_detail = COMMON.send_get_request(PRODUCT_DETAIL_API % p_id)
  File "/home/ngkhachuy/PROJECT/DEC_PJ4_TIKI.VN/COMMON.py", line 24, in send_get_request
    res_tmp = requests.get(url, headers={"user-agent":
  File "/home/ngkhachuy/anaconda3/lib/python3.9/site-packages/requests/api.py", line 73, in get
    return request("get", url, params=params, **kwargs)
  File "/home/ngkhachuy/anaconda3/lib/python3.9/site-packages/requests/api.py", line 59, in request
    return session.request(method=method, url=url, **kwargs)
  File "/home/ngkhachuy/anaconda3/lib/python3.9/site-packages/requests/sessions.py", line 587, in request
    resp = self.send(prep, **send_kwargs)
  File "/home/ngkhachuy/anaconda3/lib/python3.9/site-packages/requests/sessions.py", line 745, in send
    r.content
  File "/home/ngkhachuy/anaconda3/lib/python3.9/site-packages/requests/models.py", line 899, in content
    self._content = b"".join(self.iter_content(CONTENT_CHUNK_SIZE)) or b""
  File "/home/ngkhachuy/anaconda3/lib/python3.9/site-packages/requests/models.py", line 818, in generate
    raise ChunkedEncodingError(e)
requests.exceptions.ChunkedEncodingError: ("Connection broken: InvalidChunkLength(got length b'', 0 bytes read)", InvalidChunkLength(got length b'', 0 bytes read))

16-05-2023 13:26:50 ERROR ERROR AT CATEGORY: 21388
16-05-2023 13:26:50 ERROR ERROR AT PRODUCT: 101800785
16-05-2023 13:26:50 ERROR RESTART SCRIPT!
16-05-2023 13:26:51 INFO STARTED TIME: 13:26:51 16/05/2023
16-05-2023 13:43:51 INFO [INSERTED] Inserted 2000 Products to Category ID 21388
16-05-2023 13:59:48 ERROR HTTPSConnectionPool(host='tiki.vn', port=443): Max retries exceeded with url: /api/v2/products/241946566 (Caused by SSLError(SSLEOFError(8, 'EOF occurred in violation of protocol (_ssl.c:1129)')))
16-05-2023 13:59:59 ERROR Traceback (most recent call last):
  File "/home/ngkhachuy/anaconda3/lib/python3.9/site-packages/urllib3/connectionpool.py", line 703, in urlopen
    httplib_response = self._make_request(
  File "/home/ngkhachuy/anaconda3/lib/python3.9/site-packages/urllib3/connectionpool.py", line 386, in _make_request
    self._validate_conn(conn)
  File "/home/ngkhachuy/anaconda3/lib/python3.9/site-packages/urllib3/connectionpool.py", line 1042, in _validate_conn
    conn.connect()
  File "/home/ngkhachuy/anaconda3/lib/python3.9/site-packages/urllib3/connection.py", line 414, in connect
    self.sock = ssl_wrap_socket(
  File "/home/ngkhachuy/anaconda3/lib/python3.9/site-packages/urllib3/util/ssl_.py", line 449, in ssl_wrap_socket
    ssl_sock = _ssl_wrap_socket_impl(
  File "/home/ngkhachuy/anaconda3/lib/python3.9/site-packages/urllib3/util/ssl_.py", line 493, in _ssl_wrap_socket_impl
    return ssl_context.wrap_socket(sock, server_hostname=server_hostname)
  File "/home/ngkhachuy/anaconda3/lib/python3.9/ssl.py", line 501, in wrap_socket
    return self.sslsocket_class._create(
  File "/home/ngkhachuy/anaconda3/lib/python3.9/ssl.py", line 1041, in _create
    self.do_handshake()
  File "/home/ngkhachuy/anaconda3/lib/python3.9/ssl.py", line 1310, in do_handshake
    self._sslobj.do_handshake()
ssl.SSLEOFError: EOF occurred in violation of protocol (_ssl.c:1129)

During handling of the above exception, another exception occurred:

Traceback (most recent call last):
  File "/home/ngkhachuy/anaconda3/lib/python3.9/site-packages/requests/adapters.py", line 489, in send
    resp = conn.urlopen(
  File "/home/ngkhachuy/anaconda3/lib/python3.9/site-packages/urllib3/connectionpool.py", line 787, in urlopen
    retries = retries.increment(
  File "/home/ngkhachuy/anaconda3/lib/python3.9/site-packages/urllib3/util/retry.py", line 592, in increment
    raise MaxRetryError(_pool, url, error or ResponseError(cause))
urllib3.exceptions.MaxRetryError: HTTPSConnectionPool(host='tiki.vn', port=443): Max retries exceeded with url: /api/v2/products/241946566 (Caused by SSLError(SSLEOFError(8, 'EOF occurred in violation of protocol (_ssl.c:1129)')))

During handling of the above exception, another exception occurred:

Traceback (most recent call last):
  File "/home/ngkhachuy/PROJECT/DEC_PJ4_TIKI.VN/get_product_API.py", line 94, in <module>
    prod_detail = COMMON.send_get_request(PRODUCT_DETAIL_API % p_id)
  File "/home/ngkhachuy/PROJECT/DEC_PJ4_TIKI.VN/COMMON.py", line 24, in send_get_request
    res_tmp = requests.get(url, headers={"user-agent":
  File "/home/ngkhachuy/anaconda3/lib/python3.9/site-packages/requests/api.py", line 73, in get
    return request("get", url, params=params, **kwargs)
  File "/home/ngkhachuy/anaconda3/lib/python3.9/site-packages/requests/api.py", line 59, in request
    return session.request(method=method, url=url, **kwargs)
  File "/home/ngkhachuy/anaconda3/lib/python3.9/site-packages/requests/sessions.py", line 587, in request
    resp = self.send(prep, **send_kwargs)
  File "/home/ngkhachuy/anaconda3/lib/python3.9/site-packages/requests/sessions.py", line 701, in send
    r = adapter.send(request, **kwargs)
  File "/home/ngkhachuy/anaconda3/lib/python3.9/site-packages/requests/adapters.py", line 563, in send
    raise SSLError(e, request=request)
requests.exceptions.SSLError: HTTPSConnectionPool(host='tiki.vn', port=443): Max retries exceeded with url: /api/v2/products/241946566 (Caused by SSLError(SSLEOFError(8, 'EOF occurred in violation of protocol (_ssl.c:1129)')))

16-05-2023 13:59:59 ERROR ERROR AT CATEGORY: 21390
16-05-2023 14:00:00 ERROR ERROR AT PRODUCT: 241946566
16-05-2023 14:00:00 ERROR RESTART SCRIPT!
16-05-2023 14:22:17 INFO STARTED TIME: 14:22:17 16/05/2023
16-05-2023 14:36:42 ERROR [TIMEOUT] Restart script!
16-05-2023 14:36:42 INFO STARTED TIME: 14:36:42 16/05/2023
16-05-2023 14:39:19 INFO STARTED TIME  : 14:36:42 16/05/2023
16-05-2023 14:39:19 INFO FINISHED TIME : 14:39:19 16/05/2023
16-05-2023 14:39:19 INFO EXECUTION TINE: 0:02:36.533744
16-05-2023 14:39:19 INFO NUMBER OF REQUEST HAD BEEN SENT: 319
16-05-2023 14:42:37 INFO STARTED TIME: 14:42:37 16/05/2023
16-05-2023 14:59:07 INFO [INSERTED] Inserted 2000 Products to Category ID 21390
16-05-2023 15:00:31 INFO [INSERTED] Inserted 0141 Products to Category ID 21392
16-05-2023 15:17:10 INFO [INSERTED] Inserted 2000 Products to Category ID 21396
16-05-2023 15:34:03 INFO [INSERTED] Inserted 2000 Products to Category ID 21398
16-05-2023 15:50:52 INFO [INSERTED] Inserted 2000 Products to Category ID 21400
16-05-2023 15:52:00 INFO [INSERTED] Inserted 0148 Products to Category ID 21402
16-05-2023 16:06:42 ERROR [TIMEOUT] Restart script!
16-05-2023 16:06:43 INFO STARTED TIME: 16:06:43 16/05/2023
16-05-2023 16:23:30 INFO [INSERTED] Inserted 2000 Products to Category ID 21404
16-05-2023 16:32:55 INFO [INSERTED] Inserted 1130 Products to Category ID 21406
16-05-2023 16:32:58 INFO STARTED TIME  : 16:06:43 16/05/2023
16-05-2023 16:32:58 INFO FINISHED TIME : 16:32:58 16/05/2023
16-05-2023 16:32:58 INFO EXECUTION TINE: 0:26:14.627576
16-05-2023 16:32:58 INFO NUMBER OF REQUEST HAD BEEN SENT: 3169
